<?xml version='1.0' encoding='utf-8'?>
<robot name="estimated_robot">
  <link name="link_1">
    <visual>
      <origin xyz="-0.18430182 -0.13000733 -0.006787983" rpy="0.0 0.0 0.0" />
      <geometry>
        <mesh filename="mesh/wx200_real_5_20_seg/4_deg_20_cams/scan(0)/0001.stl" scale="1 1 1" />
      </geometry>
      <material name="material_1">
        <color rgba="0.0 0.1588235294117647 1.0 1" />
      </material>
    </visual>
    <collision>
      <origin xyz="-0.18430182 -0.13000733 -0.006787983" rpy="0.0 0.0 0.0" />
      <geometry>
        <mesh filename="mesh/wx200_real_5_20_seg/4_deg_20_cams/scan(0)/0001.stl" scale="1 1 1" />
      </geometry>
    </collision>
    <inertial>
      <origin xyz="-0.18430182 -0.13000733 -0.006787983" rpy="0.0 0.0 0.0" />
      <mass value="1.0" />
      <inertia ixx="0.1" ixy="0.0" ixz="0.0" iyy="0.1" iyz="0.0" izz="0.1" />
    </inertial>
  </link>
  <link name="link_4">
    <visual>
      <origin xyz="0.012634750555964969 0.013148338449513255 -5.7274371111644407e-05" rpy="0.0 0.0 0.0" />
      <geometry>
        <mesh filename="mesh/wx200_real_5_20_seg/4_deg_20_cams/scan(0)/0004.stl" scale="1 1 1" />
      </geometry>
      <material name="material_4">
        <color rgba="1.0 0.9012345679012348 0.0 1" />
      </material>
    </visual>
    <collision>
      <origin xyz="0.012634750555964969 0.013148338449513255 -5.7274371111644407e-05" rpy="0.0 0.0 0.0" />
      <geometry>
        <mesh filename="mesh/wx200_real_5_20_seg/4_deg_20_cams/scan(0)/0004.stl" scale="1 1 1" />
      </geometry>
    </collision>
    <inertial>
      <origin xyz="0.012634750555964969 0.013148338449513255 -5.7274371111644407e-05" rpy="0.0 0.0 0.0" />
      <mass value="1.0" />
      <inertia ixx="0.1" ixy="0.0" ixz="0.0" iyy="0.1" iyz="0.0" izz="0.1" />
    </inertial>
  </link>
  <link name="link_3">
    <visual>
      <origin xyz="-0.014526189792706895 0.10538091784020145 -0.004003466416212907" rpy="0.0 0.0 0.0" />
      <geometry>
        <mesh filename="mesh/wx200_real_5_20_seg/4_deg_20_cams/scan(0)/0003.stl" scale="1 1 1" />
      </geometry>
      <material name="material_3">
        <color rgba="0.4901960784313725 1.0 0.4775458570524984 1" />
      </material>
    </visual>
    <collision>
      <origin xyz="-0.014526189792706895 0.10538091784020145 -0.004003466416212907" rpy="0.0 0.0 0.0" />
      <geometry>
        <mesh filename="mesh/wx200_real_5_20_seg/4_deg_20_cams/scan(0)/0003.stl" scale="1 1 1" />
      </geometry>
    </collision>
    <inertial>
      <origin xyz="-0.014526189792706895 0.10538091784020145 -0.004003466416212907" rpy="0.0 0.0 0.0" />
      <mass value="1.0" />
      <inertia ixx="0.1" ixy="0.0" ixz="0.0" iyy="0.1" iyz="0.0" izz="0.1" />
    </inertial>
  </link>
  <link name="link_2">
    <visual>
      <origin xyz="0.11945212367890655 0.002064913290228232 -0.0010247768399821765" rpy="0.0 0.0 0.0" />
      <geometry>
        <mesh filename="mesh/wx200_real_5_20_seg/4_deg_20_cams/scan(0)/0002.stl" scale="1 1 1" />
      </geometry>
      <material name="material_2">
        <color rgba="0.0 0.8333333333333334 1.0 1" />
      </material>
    </visual>
    <collision>
      <origin xyz="0.11945212367890655 0.002064913290228232 -0.0010247768399821765" rpy="0.0 0.0 0.0" />
      <geometry>
        <mesh filename="mesh/wx200_real_5_20_seg/4_deg_20_cams/scan(0)/0002.stl" scale="1 1 1" />
      </geometry>
    </collision>
    <inertial>
      <origin xyz="0.11945212367890655 0.002064913290228232 -0.0010247768399821765" rpy="0.0 0.0 0.0" />
      <mass value="1.0" />
      <inertia ixx="0.1" ixy="0.0" ixz="0.0" iyy="0.1" iyz="0.0" izz="0.1" />
    </inertial>
  </link>
  <link name="link_5">
    <visual>
      <origin xyz="0.03291943928107344 -0.0006161551953696165 -0.0003109483140424892" rpy="0.0 0.0 0.0" />
      <geometry>
        <mesh filename="mesh/wx200_real_5_20_seg/4_deg_20_cams/scan(0)/0005.stl" scale="1 1 1" />
      </geometry>
      <material name="material_5">
        <color rgba="1.0 0.27668845315904156 0.0 1" />
      </material>
    </visual>
    <collision>
      <origin xyz="0.03291943928107344 -0.0006161551953696165 -0.0003109483140424892" rpy="0.0 0.0 0.0" />
      <geometry>
        <mesh filename="mesh/wx200_real_5_20_seg/4_deg_20_cams/scan(0)/0005.stl" scale="1 1 1" />
      </geometry>
    </collision>
    <inertial>
      <origin xyz="0.03291943928107344 -0.0006161551953696165 -0.0003109483140424892" rpy="0.0 0.0 0.0" />
      <mass value="1.0" />
      <inertia ixx="0.1" ixy="0.0" ixz="0.0" iyy="0.1" iyz="0.0" izz="0.1" />
    </inertial>
  </link>
  <link name="link_0">
    <visual>
      <origin xyz="0.019829850831969642 -0.006022375723373968 -0.003917213628387971" rpy="0.0 0.0 0.0" />
      <geometry>
        <mesh filename="mesh/wx200_real_5_20_seg/4_deg_20_cams/scan(0)/0000.stl" scale="1 1 1" />
      </geometry>
      <material name="material_0">
        <color rgba="0.0 0.0 0.5 1" />
      </material>
    </visual>
    <collision>
      <origin xyz="0.019829850831969642 -0.006022375723373968 -0.003917213628387971" rpy="0.0 0.0 0.0" />
      <geometry>
        <mesh filename="mesh/wx200_real_5_20_seg/4_deg_20_cams/scan(0)/0000.stl" scale="1 1 1" />
      </geometry>
    </collision>
    <inertial>
      <origin xyz="0.019829850831969642 -0.006022375723373968 -0.003917213628387971" rpy="0.0 0.0 0.0" />
      <mass value="1.0" />
      <inertia ixx="0.1" ixy="0.0" ixz="0.0" iyy="0.1" iyz="0.0" izz="0.1" />
    </inertial>
  </link>
  <joint name="joint_4" type="revolute">
    <parent link="link_1" />
    <child link="link_4" />
    <origin xyz="-0.14804517860314514 -0.09116961146644288 0.005168496992165102" rpy="0.0 0.0 0.0" />
    <axis xyz="-0.012625775580971943 0.9993448444082231 0.03391860471309886" />
    <limit effort="100" velocity="100" lower="-3.14159" upper="3.14159" />
  </joint>
  <joint name="joint_3" type="revolute">
    <parent link="link_4" />
    <child link="link_3" />
    <origin xyz="0.027661932289170216 0.048215409715490085 -0.001544697494840883" rpy="0.0 0.0 0.0" />
    <axis xyz="0.0012223725094617228 -0.00982304085182129 0.999951005636712" />
    <limit effort="100" velocity="100" lower="-3.14159" upper="3.14159" />
  </joint>
  <joint name="joint_2" type="revolute">
    <parent link="link_3" />
    <child link="link_2" />
    <origin xyz="0.03577497724121996 0.18606701043795845 -0.006539566748507108" rpy="0.0 0.0 0.0" />
    <axis xyz="-0.04582772054419138 -0.004231539998374113 0.9989403956688135" />
    <limit effort="100" velocity="100" lower="-3.14159" upper="3.14159" />
  </joint>
  <joint name="joint_5" type="revolute">
    <parent link="link_2" />
    <child link="link_5" />
    <origin xyz="0.21432516945614077 0.0003829070981543059 -0.001910259987661346" rpy="0.0 0.0 0.0" />
    <axis xyz="-0.07255256846169583 -0.11120044174438615 0.9911460974878852" />
    <limit effort="100" velocity="100" lower="-3.14159" upper="3.14159" />
  </joint>
  <joint name="joint_0" type="revolute">
    <parent link="link_5" />
    <child link="link_0" />
    <origin xyz="0.09111306683789011 -0.01640352877724391 0.0022290087271977692" rpy="0.0 0.0 0.0" />
    <axis xyz="-0.990790049171762 0.09702726623171966 0.09444992360937297" />
    <limit effort="100" velocity="100" lower="-3.14159" upper="3.14159" />
  </joint>
</robot>