<?xml version="1.0" ?>
<robot name="partnet_1f6f285ecfe0fdf786a0e7208530ce22">
	<link name="base"/>
	<link name="link_0">
		<visual name="lid-1">
			<origin xyz="0.49041753426830414 -0.42577515725760345 0.6419271146543293"/>
			<geometry>
				<mesh filename="textured_objs/original-2.obj"/>
			</geometry>
		</visual>
		<visual name="lid-1">
			<origin xyz="0.49041753426830414 -0.42577515725760345 0.6419271146543293"/>
			<geometry>
				<mesh filename="textured_objs/original-3.obj"/>
			</geometry>
		</visual>
		<collision>
			<origin xyz="0.49041753426830414 -0.42577515725760345 0.6419271146543293"/>
			<geometry>
				<mesh filename="textured_objs/original-2.obj"/>
			</geometry>
		</collision>
		<collision>
			<origin xyz="0.49041753426830414 -0.42577515725760345 0.6419271146543293"/>
			<geometry>
				<mesh filename="textured_objs/original-3.obj"/>
			</geometry>
		</collision>
	</link>
	<joint name="joint_0" type="revolute">
		<origin xyz="-0.49041753426830414 0.42577515725760345 -0.6419271146543293"/>
		<axis xyz="-0.9999959392889939 0.002349866335758954 0.0016123069581063507"/>
		<child link="link_0"/>
		<parent link="link_1"/>
		<limit lower="-0.0" upper="1.7453292519943295"/>
	</joint>
	<link name="link_1">
		<visual name="base_body-2">
			<origin xyz="0 0 0"/>
			<geometry>
				<mesh filename="textured_objs/original-4.obj"/>
			</geometry>
		</visual>
		<collision>
			<origin xyz="0 0 0"/>
			<geometry>
				<mesh filename="textured_objs/original-4.obj"/>
			</geometry>
		</collision>
	</link>
	<joint name="joint_1" type="fixed">
		<origin rpy="1.570796326794897 0 -1.570796326794897" xyz="0 0 0"/>
		<child link="link_1"/>
		<parent link="base"/>
	</joint>
</robot>
