<?xml version='1.0' encoding='utf-8'?>
<robot name="estimated_robot">
  <link name="link_0">
    <visual>
      <origin xyz="-0.040366624 0.00044639097 0.025969172" rpy="0.0 0.0 0.0" />
      <geometry>
        <mesh filename="mesh/wx200_5_20_seg/4_deg_20_cams/V0001/0000.stl" scale="1 1 1" />
      </geometry>
      <material name="material_0">
        <color rgba="0.0 0.0 0.5 1" />
      </material>
    </visual>
    <collision>
      <origin xyz="-0.040366624 0.00044639097 0.025969172" rpy="0.0 0.0 0.0" />
      <geometry>
        <mesh filename="mesh/wx200_5_20_seg/4_deg_20_cams/V0001/0000.stl" scale="1 1 1" />
      </geometry>
    </collision>
    <inertial>
      <origin xyz="-0.040366624 0.00044639097 0.025969172" rpy="0.0 0.0 0.0" />
      <mass value="1.0" />
      <inertia ixx="0.1" ixy="0.0" ixz="0.0" iyy="0.1" iyz="0.0" izz="0.1" />
    </inertial>
  </link>
  <link name="link_4">
    <visual>
      <origin xyz="0.0007262975719534971 0.0009501359352558097 0.0019091448555915297" rpy="0.0 0.0 0.0" />
      <geometry>
        <mesh filename="mesh/wx200_5_20_seg/4_deg_20_cams/V0001/0004.stl" scale="1 1 1" />
      </geometry>
      <material name="material_4">
        <color rgba="1.0 0.9012345679012348 0.0 1" />
      </material>
    </visual>
    <collision>
      <origin xyz="0.0007262975719534971 0.0009501359352558097 0.0019091448555915297" rpy="0.0 0.0 0.0" />
      <geometry>
        <mesh filename="mesh/wx200_5_20_seg/4_deg_20_cams/V0001/0004.stl" scale="1 1 1" />
      </geometry>
    </collision>
    <inertial>
      <origin xyz="0.0007262975719534971 0.0009501359352558097 0.0019091448555915297" rpy="0.0 0.0 0.0" />
      <mass value="1.0" />
      <inertia ixx="0.1" ixy="0.0" ixz="0.0" iyy="0.1" iyz="0.0" izz="0.1" />
    </inertial>
  </link>
  <link name="link_2">
    <visual>
      <origin xyz="0.003964723167726312 -0.0005737712190758746 0.11310336307720968" rpy="0.0 0.0 0.0" />
      <geometry>
        <mesh filename="mesh/wx200_5_20_seg/4_deg_20_cams/V0001/0002.stl" scale="1 1 1" />
      </geometry>
      <material name="material_2">
        <color rgba="0.0 0.8333333333333334 1.0 1" />
      </material>
    </visual>
    <collision>
      <origin xyz="0.003964723167726312 -0.0005737712190758746 0.11310336307720968" rpy="0.0 0.0 0.0" />
      <geometry>
        <mesh filename="mesh/wx200_5_20_seg/4_deg_20_cams/V0001/0002.stl" scale="1 1 1" />
      </geometry>
    </collision>
    <inertial>
      <origin xyz="0.003964723167726312 -0.0005737712190758746 0.11310336307720968" rpy="0.0 0.0 0.0" />
      <mass value="1.0" />
      <inertia ixx="0.1" ixy="0.0" ixz="0.0" iyy="0.1" iyz="0.0" izz="0.1" />
    </inertial>
  </link>
  <link name="link_1">
    <visual>
      <origin xyz="0.10189481347497786 -0.00014220636353908596 0.014168685171158657" rpy="0.0 0.0 0.0" />
      <geometry>
        <mesh filename="mesh/wx200_5_20_seg/4_deg_20_cams/V0001/0001.stl" scale="1 1 1" />
      </geometry>
      <material name="material_1">
        <color rgba="0.0 0.1588235294117647 1.0 1" />
      </material>
    </visual>
    <collision>
      <origin xyz="0.10189481347497786 -0.00014220636353908596 0.014168685171158657" rpy="0.0 0.0 0.0" />
      <geometry>
        <mesh filename="mesh/wx200_5_20_seg/4_deg_20_cams/V0001/0001.stl" scale="1 1 1" />
      </geometry>
    </collision>
    <inertial>
      <origin xyz="0.10189481347497786 -0.00014220636353908596 0.014168685171158657" rpy="0.0 0.0 0.0" />
      <mass value="1.0" />
      <inertia ixx="0.1" ixy="0.0" ixz="0.0" iyy="0.1" iyz="0.0" izz="0.1" />
    </inertial>
  </link>
  <link name="link_5">
    <visual>
      <origin xyz="0.040502059520110156 1.9808442374084478e-05 0.009014299945731774" rpy="0.0 0.0 0.0" />
      <geometry>
        <mesh filename="mesh/wx200_5_20_seg/4_deg_20_cams/V0001/0005.stl" scale="1 1 1" />
      </geometry>
      <material name="material_5">
        <color rgba="1.0 0.27668845315904156 0.0 1" />
      </material>
    </visual>
    <collision>
      <origin xyz="0.040502059520110156 1.9808442374084478e-05 0.009014299945731774" rpy="0.0 0.0 0.0" />
      <geometry>
        <mesh filename="mesh/wx200_5_20_seg/4_deg_20_cams/V0001/0005.stl" scale="1 1 1" />
      </geometry>
    </collision>
    <inertial>
      <origin xyz="0.040502059520110156 1.9808442374084478e-05 0.009014299945731774" rpy="0.0 0.0 0.0" />
      <mass value="1.0" />
      <inertia ixx="0.1" ixy="0.0" ixz="0.0" iyy="0.1" iyz="0.0" izz="0.1" />
    </inertial>
  </link>
  <link name="link_3">
    <visual>
      <origin xyz="0.030066329183957297 0.0033699107494504547 0.00233245896839801" rpy="0.0 0.0 0.0" />
      <geometry>
        <mesh filename="mesh/wx200_5_20_seg/4_deg_20_cams/V0001/0003.stl" scale="1 1 1" />
      </geometry>
      <material name="material_3">
        <color rgba="0.4901960784313725 1.0 0.4775458570524984 1" />
      </material>
    </visual>
    <collision>
      <origin xyz="0.030066329183957297 0.0033699107494504547 0.00233245896839801" rpy="0.0 0.0 0.0" />
      <geometry>
        <mesh filename="mesh/wx200_5_20_seg/4_deg_20_cams/V0001/0003.stl" scale="1 1 1" />
      </geometry>
    </collision>
    <inertial>
      <origin xyz="0.030066329183957297 0.0033699107494504547 0.00233245896839801" rpy="0.0 0.0 0.0" />
      <mass value="1.0" />
      <inertia ixx="0.1" ixy="0.0" ixz="0.0" iyy="0.1" iyz="0.0" izz="0.1" />
    </inertial>
  </link>
  <joint name="joint_4" type="revolute">
    <parent link="link_0" />
    <child link="link_4" />
    <origin xyz="-0.00026076643697556245 3.005592881746681e-05 0.08922468807592702" rpy="0.0 0.0 0.0" />
    <axis xyz="-0.0018128939652158902 -0.00772474890796904 0.9999685203394053" />
    <limit effort="100" velocity="100" lower="-3.14159" upper="3.14159" />
  </joint>
  <joint name="joint_2" type="revolute">
    <parent link="link_4" />
    <child link="link_2" />
    <origin xyz="0.0023369907810414313 0.000830237146000147 0.023942907628105664" rpy="0.0 0.0 0.0" />
    <axis xyz="-0.009156687286981439 -0.9999451824364811 0.005078109884679441" />
    <limit effort="100" velocity="100" lower="-3.14159" upper="3.14159" />
  </joint>
  <joint name="joint_1" type="revolute">
    <parent link="link_2" />
    <child link="link_1" />
    <origin xyz="0.05209488813672866 -0.00035994705176760247 0.19194914168836152" rpy="0.0 0.0 0.0" />
    <axis xyz="0.007630275620063241 0.9999708761237283 -0.0001606185081530764" />
    <limit effort="100" velocity="100" lower="-3.14159" upper="3.14159" />
  </joint>
  <joint name="joint_5" type="revolute">
    <parent link="link_1" />
    <child link="link_5" />
    <origin xyz="0.20262603425596176 3.524039223211481e-05 0.020513399498116702" rpy="0.0 0.0 0.0" />
    <axis xyz="0.021061617020567875 -0.9997641032288191 -0.0053052976875819545" />
    <limit effort="100" velocity="100" lower="-3.14159" upper="3.14159" />
  </joint>
  <joint name="joint_3" type="revolute">
    <parent link="link_5" />
    <child link="link_3" />
    <origin xyz="0.08833134186073477 -0.003311759174602842 -0.009244490304328223" rpy="0.0 0.0 0.0" />
    <axis xyz="-0.99223256864779 0.0461813558347838 0.11550676208720329" />
    <limit effort="100" velocity="100" lower="-3.14159" upper="3.14159" />
  </joint>
</robot>