<?xml version="1.0" ?>
<!-- =================================================================================== -->
<!-- |    This document was autogenerated by xacro from pxmark4s.urdf.xacro            | -->
<!-- |    EDITING THIS FILE BY HAND IS NOT RECOMMENDED                                 | -->
<!-- =================================================================================== -->
<robot name="pxmark4s">
  <material name="interbotix_black">
    <texture filename="package://interbotix_xshexapod_descriptions/meshes/interbotix_black.png"/>
  </material>
  <link name="pxmark4s/base_link">
    <visual>
      <origin rpy="0 0 0" xyz="0 0 0"/>
      <geometry>
        <mesh filename="package://interbotix_xshexapod_descriptions/meshes/pxmark4s_meshes/pxmark4s_base_link.stl" scale="0.001 0.001 0.001"/>
      </geometry>
      <material name="interbotix_black"/>
    </visual>
    <collision>
      <origin rpy="0 0 0" xyz="0 0 0"/>
      <geometry>
        <mesh filename="package://interbotix_xshexapod_descriptions/meshes/pxmark4s_meshes/pxmark4s_base_link.stl" scale="0.001 0.001 0.001"/>
      </geometry>
    </collision>
    <inertial>
      <origin rpy="0 0 0" xyz="0.001481 0.000294 0.014944"/>
      <mass value="1.564057"/>
      <inertia ixx="0.0046750000" ixy="0.0000076888" ixz="-0.0001245000" iyy="0.0088790000" iyz="0.0000050996" izz="0.0097940000"/>
    </inertial>
  </link>
  <joint name="base_bottom" type="fixed">
    <origin rpy="0 0 0" xyz="0 0 -0.033"/>
    <parent link="pxmark4s/base_link"/>
    <child link="pxmark4s/base_bottom_link"/>
  </joint>
  <link name="pxmark4s/base_bottom_link">
  </link>
  <joint name="right_front_coxa" type="revolute">
    <axis xyz="0 0 1"/>
    <limit effort="3" lower="-0.9599310885968813" upper="0.9599310885968813" velocity="3.141592653589793"/>
    <origin rpy="0 0 -0.7853981633974483" xyz="0.125 -0.065 0"/>
    <parent link="pxmark4s/base_link"/>
    <child link="pxmark4s/right_front_coxa_link"/>
  </joint>
  <transmission name="trans_right_front_coxa">
    <type>transmission_interface/SimpleTransmission</type>
    <joint name="right_front_coxa">
      <hardwareInterface>hardware_interface/EffortJointInterface</hardwareInterface>
    </joint>
    <actuator name="right_front_coxa_motor">
      <mechanicalReduction>1</mechanicalReduction>
    </actuator>
  </transmission>
  <link name="pxmark4s/right_front_coxa_link">
    <visual>
      <origin rpy="0 0 0" xyz="0 0 0"/>
      <geometry>
        <mesh filename="package://interbotix_xshexapod_descriptions/meshes/pxmark4s_meshes/pxmark4s_coxa_link.stl" scale="0.001 0.001 0.001"/>
      </geometry>
      <material name="interbotix_black"/>
    </visual>
    <collision>
      <origin rpy="0 0 0" xyz="0 0 0"/>
      <geometry>
        <mesh filename="package://interbotix_xshexapod_descriptions/meshes/pxmark4s_meshes/pxmark4s_coxa_link.stl" scale="0.001 0.001 0.001"/>
      </geometry>
    </collision>
    <inertial>
      <origin rpy="0 0 0" xyz="0.019066 -0.000002 0.006577"/>
      <mass value="0.02471"/>
      <inertia ixx="0.0000215400" ixy="-0.00000000122" ixz="-0.00000192741" iyy="0.00002657000" iyz="-0.00000000001" izz="0.00002925000"/>
    </inertial>
  </link>
  <joint name="right_front_femur" type="revolute">
    <axis xyz="0 1 0"/>
    <limit effort="3" lower="-1.710422666954443" upper="1.5707963267948966" velocity="3.141592653589793"/>
    <origin rpy="0 0 0" xyz="0.052907539 0 0"/>
    <parent link="pxmark4s/right_front_coxa_link"/>
    <child link="pxmark4s/right_front_femur_link"/>
  </joint>
  <transmission name="trans_right_front_femur">
    <type>transmission_interface/SimpleTransmission</type>
    <joint name="right_front_femur">
      <hardwareInterface>hardware_interface/EffortJointInterface</hardwareInterface>
    </joint>
    <actuator name="right_front_femur_motor">
      <mechanicalReduction>1</mechanicalReduction>
    </actuator>
  </transmission>
  <link name="pxmark4s/right_front_femur_link">
    <visual>
      <origin rpy="0 0 0" xyz="0 0 0"/>
      <geometry>
        <mesh filename="package://interbotix_xshexapod_descriptions/meshes/pxmark4s_meshes/pxmark4s_femur_link.stl" scale="0.001 0.001 0.001"/>
      </geometry>
      <material name="interbotix_black"/>
    </visual>
    <collision>
      <origin rpy="0 0 0" xyz="0 0 0"/>
      <geometry>
        <mesh filename="package://interbotix_xshexapod_descriptions/meshes/pxmark4s_meshes/pxmark4s_femur_link.stl" scale="0.001 0.001 0.001"/>
      </geometry>
    </collision>
    <inertial>
      <origin rpy="0 0 0" xyz="0.019579 -0.000301 -0.000582"/>
      <mass value="0.092834"/>
      <inertia ixx="0.0000300200" ixy="0.0000002711" ixz="0.0000048494" iyy="0.0000776600" iyz="0.0000000003" izz="0.0000896200"/>
    </inertial>
  </link>
  <joint name="right_front_tibia" type="revolute">
    <axis xyz="0 1 0"/>
    <limit effort="3" lower="-0.7853981633974483" upper="2.181661564992912" velocity="3.141592653589793"/>
    <origin rpy="0 0 0" xyz="0.06 0 -0.015"/>
    <parent link="pxmark4s/right_front_femur_link"/>
    <child link="pxmark4s/right_front_tibia_link"/>
  </joint>
  <transmission name="trans_right_front_tibia">
    <type>transmission_interface/SimpleTransmission</type>
    <joint name="right_front_tibia">
      <hardwareInterface>hardware_interface/EffortJointInterface</hardwareInterface>
    </joint>
    <actuator name="right_front_tibia_motor">
      <mechanicalReduction>1</mechanicalReduction>
    </actuator>
  </transmission>
  <link name="pxmark4s/right_front_tibia_link">
    <visual>
      <origin rpy="0 0 0" xyz="0 0 0"/>
      <geometry>
        <mesh filename="package://interbotix_xshexapod_descriptions/meshes/pxmark4s_meshes/pxmark4s_tibia_link.stl" scale="0.001 0.001 0.001"/>
      </geometry>
      <material name="interbotix_black"/>
    </visual>
    <collision>
      <origin rpy="0 0 0" xyz="0 0 0"/>
      <geometry>
        <mesh filename="package://interbotix_xshexapod_descriptions/meshes/pxmark4s_meshes/pxmark4s_tibia_link.stl" scale="0.001 0.001 0.001"/>
      </geometry>
    </collision>
    <inertial>
      <origin rpy="0 0 0" xyz="0.035812 0.000035 -0.011522"/>
      <mass value="0.178825"/>
      <inertia ixx="0.0001773000" ixy="-0.0000014230" ixz="0.0001789000" iyy="0.0005185000" iyz="0.0000006181" izz="0.0003797000"/>
    </inertial>
  </link>
  <joint name="right_front_foot" type="fixed">
    <origin rpy="0 0 0" xyz="0.095 0 -0.09"/>
    <parent link="pxmark4s/right_front_tibia_link"/>
    <child link="pxmark4s/right_front_foot_link"/>
  </joint>
  <link name="pxmark4s/right_front_foot_link"/>
  <joint name="right_middle_coxa" type="revolute">
    <axis xyz="0 0 1"/>
    <limit effort="3" lower="-0.9599310885968813" upper="0.9599310885968813" velocity="3.141592653589793"/>
    <origin rpy="0 0 -1.5707963267948966" xyz="0 -0.1 0"/>
    <parent link="pxmark4s/base_link"/>
    <child link="pxmark4s/right_middle_coxa_link"/>
  </joint>
  <transmission name="trans_right_middle_coxa">
    <type>transmission_interface/SimpleTransmission</type>
    <joint name="right_middle_coxa">
      <hardwareInterface>hardware_interface/EffortJointInterface</hardwareInterface>
    </joint>
    <actuator name="right_middle_coxa_motor">
      <mechanicalReduction>1</mechanicalReduction>
    </actuator>
  </transmission>
  <link name="pxmark4s/right_middle_coxa_link">
    <visual>
      <origin rpy="0 0 0" xyz="0 0 0"/>
      <geometry>
        <mesh filename="package://interbotix_xshexapod_descriptions/meshes/pxmark4s_meshes/pxmark4s_coxa_link.stl" scale="0.001 0.001 0.001"/>
      </geometry>
      <material name="interbotix_black"/>
    </visual>
    <collision>
      <origin rpy="0 0 0" xyz="0 0 0"/>
      <geometry>
        <mesh filename="package://interbotix_xshexapod_descriptions/meshes/pxmark4s_meshes/pxmark4s_coxa_link.stl" scale="0.001 0.001 0.001"/>
      </geometry>
    </collision>
    <inertial>
      <origin rpy="0 0 0" xyz="0.019066 -0.000002 0.006577"/>
      <mass value="0.02471"/>
      <inertia ixx="0.0000215400" ixy="-0.00000000122" ixz="-0.00000192741" iyy="0.00002657000" iyz="-0.00000000001" izz="0.00002925000"/>
    </inertial>
  </link>
  <joint name="right_middle_femur" type="revolute">
    <axis xyz="0 1 0"/>
    <limit effort="3" lower="-1.710422666954443" upper="1.5707963267948966" velocity="3.141592653589793"/>
    <origin rpy="0 0 0" xyz="0.052907539 0 0"/>
    <parent link="pxmark4s/right_middle_coxa_link"/>
    <child link="pxmark4s/right_middle_femur_link"/>
  </joint>
  <transmission name="trans_right_middle_femur">
    <type>transmission_interface/SimpleTransmission</type>
    <joint name="right_middle_femur">
      <hardwareInterface>hardware_interface/EffortJointInterface</hardwareInterface>
    </joint>
    <actuator name="right_middle_femur_motor">
      <mechanicalReduction>1</mechanicalReduction>
    </actuator>
  </transmission>
  <link name="pxmark4s/right_middle_femur_link">
    <visual>
      <origin rpy="0 0 0" xyz="0 0 0"/>
      <geometry>
        <mesh filename="package://interbotix_xshexapod_descriptions/meshes/pxmark4s_meshes/pxmark4s_femur_link.stl" scale="0.001 0.001 0.001"/>
      </geometry>
      <material name="interbotix_black"/>
    </visual>
    <collision>
      <origin rpy="0 0 0" xyz="0 0 0"/>
      <geometry>
        <mesh filename="package://interbotix_xshexapod_descriptions/meshes/pxmark4s_meshes/pxmark4s_femur_link.stl" scale="0.001 0.001 0.001"/>
      </geometry>
    </collision>
    <inertial>
      <origin rpy="0 0 0" xyz="0.019579 -0.000301 -0.000582"/>
      <mass value="0.092834"/>
      <inertia ixx="0.0000300200" ixy="0.0000002711" ixz="0.0000048494" iyy="0.0000776600" iyz="0.0000000003" izz="0.0000896200"/>
    </inertial>
  </link>
  <joint name="right_middle_tibia" type="revolute">
    <axis xyz="0 1 0"/>
    <limit effort="3" lower="-0.7853981633974483" upper="2.181661564992912" velocity="3.141592653589793"/>
    <origin rpy="0 0 0" xyz="0.06 0 -0.015"/>
    <parent link="pxmark4s/right_middle_femur_link"/>
    <child link="pxmark4s/right_middle_tibia_link"/>
  </joint>
  <transmission name="trans_right_middle_tibia">
    <type>transmission_interface/SimpleTransmission</type>
    <joint name="right_middle_tibia">
      <hardwareInterface>hardware_interface/EffortJointInterface</hardwareInterface>
    </joint>
    <actuator name="right_middle_tibia_motor">
      <mechanicalReduction>1</mechanicalReduction>
    </actuator>
  </transmission>
  <link name="pxmark4s/right_middle_tibia_link">
    <visual>
      <origin rpy="0 0 0" xyz="0 0 0"/>
      <geometry>
        <mesh filename="package://interbotix_xshexapod_descriptions/meshes/pxmark4s_meshes/pxmark4s_tibia_link.stl" scale="0.001 0.001 0.001"/>
      </geometry>
      <material name="interbotix_black"/>
    </visual>
    <collision>
      <origin rpy="0 0 0" xyz="0 0 0"/>
      <geometry>
        <mesh filename="package://interbotix_xshexapod_descriptions/meshes/pxmark4s_meshes/pxmark4s_tibia_link.stl" scale="0.001 0.001 0.001"/>
      </geometry>
    </collision>
    <inertial>
      <origin rpy="0 0 0" xyz="0.035812 0.000035 -0.011522"/>
      <mass value="0.178825"/>
      <inertia ixx="0.0001773000" ixy="-0.0000014230" ixz="0.0001789000" iyy="0.0005185000" iyz="0.0000006181" izz="0.0003797000"/>
    </inertial>
  </link>
  <joint name="right_middle_foot" type="fixed">
    <origin rpy="0 0 0" xyz="0.095 0 -0.09"/>
    <parent link="pxmark4s/right_middle_tibia_link"/>
    <child link="pxmark4s/right_middle_foot_link"/>
  </joint>
  <link name="pxmark4s/right_middle_foot_link"/>
  <joint name="right_back_coxa" type="revolute">
    <axis xyz="0 0 1"/>
    <limit effort="3" lower="-0.9599310885968813" upper="0.9599310885968813" velocity="3.141592653589793"/>
    <origin rpy="0 0 -2.356194490192345" xyz="-0.125 -0.065 0"/>
    <parent link="pxmark4s/base_link"/>
    <child link="pxmark4s/right_back_coxa_link"/>
  </joint>
  <transmission name="trans_right_back_coxa">
    <type>transmission_interface/SimpleTransmission</type>
    <joint name="right_back_coxa">
      <hardwareInterface>hardware_interface/EffortJointInterface</hardwareInterface>
    </joint>
    <actuator name="right_back_coxa_motor">
      <mechanicalReduction>1</mechanicalReduction>
    </actuator>
  </transmission>
  <link name="pxmark4s/right_back_coxa_link">
    <visual>
      <origin rpy="0 0 0" xyz="0 0 0"/>
      <geometry>
        <mesh filename="package://interbotix_xshexapod_descriptions/meshes/pxmark4s_meshes/pxmark4s_coxa_link.stl" scale="0.001 0.001 0.001"/>
      </geometry>
      <material name="interbotix_black"/>
    </visual>
    <collision>
      <origin rpy="0 0 0" xyz="0 0 0"/>
      <geometry>
        <mesh filename="package://interbotix_xshexapod_descriptions/meshes/pxmark4s_meshes/pxmark4s_coxa_link.stl" scale="0.001 0.001 0.001"/>
      </geometry>
    </collision>
    <inertial>
      <origin rpy="0 0 0" xyz="0.019066 -0.000002 0.006577"/>
      <mass value="0.02471"/>
      <inertia ixx="0.0000215400" ixy="-0.00000000122" ixz="-0.00000192741" iyy="0.00002657000" iyz="-0.00000000001" izz="0.00002925000"/>
    </inertial>
  </link>
  <joint name="right_back_femur" type="revolute">
    <axis xyz="0 1 0"/>
    <limit effort="3" lower="-1.710422666954443" upper="1.5707963267948966" velocity="3.141592653589793"/>
    <origin rpy="0 0 0" xyz="0.052907539 0 0"/>
    <parent link="pxmark4s/right_back_coxa_link"/>
    <child link="pxmark4s/right_back_femur_link"/>
  </joint>
  <transmission name="trans_right_back_femur">
    <type>transmission_interface/SimpleTransmission</type>
    <joint name="right_back_femur">
      <hardwareInterface>hardware_interface/EffortJointInterface</hardwareInterface>
    </joint>
    <actuator name="right_back_femur_motor">
      <mechanicalReduction>1</mechanicalReduction>
    </actuator>
  </transmission>
  <link name="pxmark4s/right_back_femur_link">
    <visual>
      <origin rpy="0 0 0" xyz="0 0 0"/>
      <geometry>
        <mesh filename="package://interbotix_xshexapod_descriptions/meshes/pxmark4s_meshes/pxmark4s_femur_link.stl" scale="0.001 0.001 0.001"/>
      </geometry>
      <material name="interbotix_black"/>
    </visual>
    <collision>
      <origin rpy="0 0 0" xyz="0 0 0"/>
      <geometry>
        <mesh filename="package://interbotix_xshexapod_descriptions/meshes/pxmark4s_meshes/pxmark4s_femur_link.stl" scale="0.001 0.001 0.001"/>
      </geometry>
    </collision>
    <inertial>
      <origin rpy="0 0 0" xyz="0.019579 -0.000301 -0.000582"/>
      <mass value="0.092834"/>
      <inertia ixx="0.0000300200" ixy="0.0000002711" ixz="0.0000048494" iyy="0.0000776600" iyz="0.0000000003" izz="0.0000896200"/>
    </inertial>
  </link>
  <joint name="right_back_tibia" type="revolute">
    <axis xyz="0 1 0"/>
    <limit effort="3" lower="-0.7853981633974483" upper="2.181661564992912" velocity="3.141592653589793"/>
    <origin rpy="0 0 0" xyz="0.06 0 -0.015"/>
    <parent link="pxmark4s/right_back_femur_link"/>
    <child link="pxmark4s/right_back_tibia_link"/>
  </joint>
  <transmission name="trans_right_back_tibia">
    <type>transmission_interface/SimpleTransmission</type>
    <joint name="right_back_tibia">
      <hardwareInterface>hardware_interface/EffortJointInterface</hardwareInterface>
    </joint>
    <actuator name="right_back_tibia_motor">
      <mechanicalReduction>1</mechanicalReduction>
    </actuator>
  </transmission>
  <link name="pxmark4s/right_back_tibia_link">
    <visual>
      <origin rpy="0 0 0" xyz="0 0 0"/>
      <geometry>
        <mesh filename="package://interbotix_xshexapod_descriptions/meshes/pxmark4s_meshes/pxmark4s_tibia_link.stl" scale="0.001 0.001 0.001"/>
      </geometry>
      <material name="interbotix_black"/>
    </visual>
    <collision>
      <origin rpy="0 0 0" xyz="0 0 0"/>
      <geometry>
        <mesh filename="package://interbotix_xshexapod_descriptions/meshes/pxmark4s_meshes/pxmark4s_tibia_link.stl" scale="0.001 0.001 0.001"/>
      </geometry>
    </collision>
    <inertial>
      <origin rpy="0 0 0" xyz="0.035812 0.000035 -0.011522"/>
      <mass value="0.178825"/>
      <inertia ixx="0.0001773000" ixy="-0.0000014230" ixz="0.0001789000" iyy="0.0005185000" iyz="0.0000006181" izz="0.0003797000"/>
    </inertial>
  </link>
  <joint name="right_back_foot" type="fixed">
    <origin rpy="0 0 0" xyz="0.095 0 -0.09"/>
    <parent link="pxmark4s/right_back_tibia_link"/>
    <child link="pxmark4s/right_back_foot_link"/>
  </joint>
  <link name="pxmark4s/right_back_foot_link"/>
  <joint name="left_front_coxa" type="revolute">
    <axis xyz="0 0 1"/>
    <limit effort="3" lower="-0.9599310885968813" upper="0.9599310885968813" velocity="3.141592653589793"/>
    <origin rpy="0 0 0.7853981633974483" xyz="0.125 0.065 0"/>
    <parent link="pxmark4s/base_link"/>
    <child link="pxmark4s/left_front_coxa_link"/>
  </joint>
  <transmission name="trans_left_front_coxa">
    <type>transmission_interface/SimpleTransmission</type>
    <joint name="left_front_coxa">
      <hardwareInterface>hardware_interface/EffortJointInterface</hardwareInterface>
    </joint>
    <actuator name="left_front_coxa_motor">
      <mechanicalReduction>1</mechanicalReduction>
    </actuator>
  </transmission>
  <link name="pxmark4s/left_front_coxa_link">
    <visual>
      <origin rpy="0 0 0" xyz="0 0 0"/>
      <geometry>
        <mesh filename="package://interbotix_xshexapod_descriptions/meshes/pxmark4s_meshes/pxmark4s_coxa_link.stl" scale="0.001 0.001 0.001"/>
      </geometry>
      <material name="interbotix_black"/>
    </visual>
    <collision>
      <origin rpy="0 0 0" xyz="0 0 0"/>
      <geometry>
        <mesh filename="package://interbotix_xshexapod_descriptions/meshes/pxmark4s_meshes/pxmark4s_coxa_link.stl" scale="0.001 0.001 0.001"/>
      </geometry>
    </collision>
    <inertial>
      <origin rpy="0 0 0" xyz="0.019066 -0.000002 0.006577"/>
      <mass value="0.02471"/>
      <inertia ixx="0.0000215400" ixy="-0.00000000122" ixz="-0.00000192741" iyy="0.00002657000" iyz="-0.00000000001" izz="0.00002925000"/>
    </inertial>
  </link>
  <joint name="left_front_femur" type="revolute">
    <axis xyz="0 1 0"/>
    <limit effort="3" lower="-1.710422666954443" upper="1.5707963267948966" velocity="3.141592653589793"/>
    <origin rpy="0 0 0" xyz="0.052907539 0 0"/>
    <parent link="pxmark4s/left_front_coxa_link"/>
    <child link="pxmark4s/left_front_femur_link"/>
  </joint>
  <transmission name="trans_left_front_femur">
    <type>transmission_interface/SimpleTransmission</type>
    <joint name="left_front_femur">
      <hardwareInterface>hardware_interface/EffortJointInterface</hardwareInterface>
    </joint>
    <actuator name="left_front_femur_motor">
      <mechanicalReduction>1</mechanicalReduction>
    </actuator>
  </transmission>
  <link name="pxmark4s/left_front_femur_link">
    <visual>
      <origin rpy="0 0 0" xyz="0 0 0"/>
      <geometry>
        <mesh filename="package://interbotix_xshexapod_descriptions/meshes/pxmark4s_meshes/pxmark4s_femur_link.stl" scale="0.001 0.001 0.001"/>
      </geometry>
      <material name="interbotix_black"/>
    </visual>
    <collision>
      <origin rpy="0 0 0" xyz="0 0 0"/>
      <geometry>
        <mesh filename="package://interbotix_xshexapod_descriptions/meshes/pxmark4s_meshes/pxmark4s_femur_link.stl" scale="0.001 0.001 0.001"/>
      </geometry>
    </collision>
    <inertial>
      <origin rpy="0 0 0" xyz="0.019579 -0.000301 -0.000582"/>
      <mass value="0.092834"/>
      <inertia ixx="0.0000300200" ixy="0.0000002711" ixz="0.0000048494" iyy="0.0000776600" iyz="0.0000000003" izz="0.0000896200"/>
    </inertial>
  </link>
  <joint name="left_front_tibia" type="revolute">
    <axis xyz="0 1 0"/>
    <limit effort="3" lower="-0.7853981633974483" upper="2.181661564992912" velocity="3.141592653589793"/>
    <origin rpy="0 0 0" xyz="0.06 0 -0.015"/>
    <parent link="pxmark4s/left_front_femur_link"/>
    <child link="pxmark4s/left_front_tibia_link"/>
  </joint>
  <transmission name="trans_left_front_tibia">
    <type>transmission_interface/SimpleTransmission</type>
    <joint name="left_front_tibia">
      <hardwareInterface>hardware_interface/EffortJointInterface</hardwareInterface>
    </joint>
    <actuator name="left_front_tibia_motor">
      <mechanicalReduction>1</mechanicalReduction>
    </actuator>
  </transmission>
  <link name="pxmark4s/left_front_tibia_link">
    <visual>
      <origin rpy="0 0 0" xyz="0 0 0"/>
      <geometry>
        <mesh filename="package://interbotix_xshexapod_descriptions/meshes/pxmark4s_meshes/pxmark4s_tibia_link.stl" scale="0.001 0.001 0.001"/>
      </geometry>
      <material name="interbotix_black"/>
    </visual>
    <collision>
      <origin rpy="0 0 0" xyz="0 0 0"/>
      <geometry>
        <mesh filename="package://interbotix_xshexapod_descriptions/meshes/pxmark4s_meshes/pxmark4s_tibia_link.stl" scale="0.001 0.001 0.001"/>
      </geometry>
    </collision>
    <inertial>
      <origin rpy="0 0 0" xyz="0.035812 0.000035 -0.011522"/>
      <mass value="0.178825"/>
      <inertia ixx="0.0001773000" ixy="-0.0000014230" ixz="0.0001789000" iyy="0.0005185000" iyz="0.0000006181" izz="0.0003797000"/>
    </inertial>
  </link>
  <joint name="left_front_foot" type="fixed">
    <origin rpy="0 0 0" xyz="0.095 0 -0.09"/>
    <parent link="pxmark4s/left_front_tibia_link"/>
    <child link="pxmark4s/left_front_foot_link"/>
  </joint>
  <link name="pxmark4s/left_front_foot_link"/>
  <joint name="left_middle_coxa" type="revolute">
    <axis xyz="0 0 1"/>
    <limit effort="3" lower="-0.9599310885968813" upper="0.9599310885968813" velocity="3.141592653589793"/>
    <origin rpy="0 0 1.5707963267948966" xyz="0 0.1 0"/>
    <parent link="pxmark4s/base_link"/>
    <child link="pxmark4s/left_middle_coxa_link"/>
  </joint>
  <transmission name="trans_left_middle_coxa">
    <type>transmission_interface/SimpleTransmission</type>
    <joint name="left_middle_coxa">
      <hardwareInterface>hardware_interface/EffortJointInterface</hardwareInterface>
    </joint>
    <actuator name="left_middle_coxa_motor">
      <mechanicalReduction>1</mechanicalReduction>
    </actuator>
  </transmission>
  <link name="pxmark4s/left_middle_coxa_link">
    <visual>
      <origin rpy="0 0 0" xyz="0 0 0"/>
      <geometry>
        <mesh filename="package://interbotix_xshexapod_descriptions/meshes/pxmark4s_meshes/pxmark4s_coxa_link.stl" scale="0.001 0.001 0.001"/>
      </geometry>
      <material name="interbotix_black"/>
    </visual>
    <collision>
      <origin rpy="0 0 0" xyz="0 0 0"/>
      <geometry>
        <mesh filename="package://interbotix_xshexapod_descriptions/meshes/pxmark4s_meshes/pxmark4s_coxa_link.stl" scale="0.001 0.001 0.001"/>
      </geometry>
    </collision>
    <inertial>
      <origin rpy="0 0 0" xyz="0.019066 -0.000002 0.006577"/>
      <mass value="0.02471"/>
      <inertia ixx="0.0000215400" ixy="-0.00000000122" ixz="-0.00000192741" iyy="0.00002657000" iyz="-0.00000000001" izz="0.00002925000"/>
    </inertial>
  </link>
  <joint name="left_middle_femur" type="revolute">
    <axis xyz="0 1 0"/>
    <limit effort="3" lower="-1.710422666954443" upper="1.5707963267948966" velocity="3.141592653589793"/>
    <origin rpy="0 0 0" xyz="0.052907539 0 0"/>
    <parent link="pxmark4s/left_middle_coxa_link"/>
    <child link="pxmark4s/left_middle_femur_link"/>
  </joint>
  <transmission name="trans_left_middle_femur">
    <type>transmission_interface/SimpleTransmission</type>
    <joint name="left_middle_femur">
      <hardwareInterface>hardware_interface/EffortJointInterface</hardwareInterface>
    </joint>
    <actuator name="left_middle_femur_motor">
      <mechanicalReduction>1</mechanicalReduction>
    </actuator>
  </transmission>
  <link name="pxmark4s/left_middle_femur_link">
    <visual>
      <origin rpy="0 0 0" xyz="0 0 0"/>
      <geometry>
        <mesh filename="package://interbotix_xshexapod_descriptions/meshes/pxmark4s_meshes/pxmark4s_femur_link.stl" scale="0.001 0.001 0.001"/>
      </geometry>
      <material name="interbotix_black"/>
    </visual>
    <collision>
      <origin rpy="0 0 0" xyz="0 0 0"/>
      <geometry>
        <mesh filename="package://interbotix_xshexapod_descriptions/meshes/pxmark4s_meshes/pxmark4s_femur_link.stl" scale="0.001 0.001 0.001"/>
      </geometry>
    </collision>
    <inertial>
      <origin rpy="0 0 0" xyz="0.019579 -0.000301 -0.000582"/>
      <mass value="0.092834"/>
      <inertia ixx="0.0000300200" ixy="0.0000002711" ixz="0.0000048494" iyy="0.0000776600" iyz="0.0000000003" izz="0.0000896200"/>
    </inertial>
  </link>
  <joint name="left_middle_tibia" type="revolute">
    <axis xyz="0 1 0"/>
    <limit effort="3" lower="-0.7853981633974483" upper="2.181661564992912" velocity="3.141592653589793"/>
    <origin rpy="0 0 0" xyz="0.06 0 -0.015"/>
    <parent link="pxmark4s/left_middle_femur_link"/>
    <child link="pxmark4s/left_middle_tibia_link"/>
  </joint>
  <transmission name="trans_left_middle_tibia">
    <type>transmission_interface/SimpleTransmission</type>
    <joint name="left_middle_tibia">
      <hardwareInterface>hardware_interface/EffortJointInterface</hardwareInterface>
    </joint>
    <actuator name="left_middle_tibia_motor">
      <mechanicalReduction>1</mechanicalReduction>
    </actuator>
  </transmission>
  <link name="pxmark4s/left_middle_tibia_link">
    <visual>
      <origin rpy="0 0 0" xyz="0 0 0"/>
      <geometry>
        <mesh filename="package://interbotix_xshexapod_descriptions/meshes/pxmark4s_meshes/pxmark4s_tibia_link.stl" scale="0.001 0.001 0.001"/>
      </geometry>
      <material name="interbotix_black"/>
    </visual>
    <collision>
      <origin rpy="0 0 0" xyz="0 0 0"/>
      <geometry>
        <mesh filename="package://interbotix_xshexapod_descriptions/meshes/pxmark4s_meshes/pxmark4s_tibia_link.stl" scale="0.001 0.001 0.001"/>
      </geometry>
    </collision>
    <inertial>
      <origin rpy="0 0 0" xyz="0.035812 0.000035 -0.011522"/>
      <mass value="0.178825"/>
      <inertia ixx="0.0001773000" ixy="-0.0000014230" ixz="0.0001789000" iyy="0.0005185000" iyz="0.0000006181" izz="0.0003797000"/>
    </inertial>
  </link>
  <joint name="left_middle_foot" type="fixed">
    <origin rpy="0 0 0" xyz="0.095 0 -0.09"/>
    <parent link="pxmark4s/left_middle_tibia_link"/>
    <child link="pxmark4s/left_middle_foot_link"/>
  </joint>
  <link name="pxmark4s/left_middle_foot_link"/>
  <joint name="left_back_coxa" type="revolute">
    <axis xyz="0 0 1"/>
    <limit effort="3" lower="-0.9599310885968813" upper="0.9599310885968813" velocity="3.141592653589793"/>
    <origin rpy="0 0 2.356194490192345" xyz="-0.125 0.065 0"/>
    <parent link="pxmark4s/base_link"/>
    <child link="pxmark4s/left_back_coxa_link"/>
  </joint>
  <transmission name="trans_left_back_coxa">
    <type>transmission_interface/SimpleTransmission</type>
    <joint name="left_back_coxa">
      <hardwareInterface>hardware_interface/EffortJointInterface</hardwareInterface>
    </joint>
    <actuator name="left_back_coxa_motor">
      <mechanicalReduction>1</mechanicalReduction>
    </actuator>
  </transmission>
  <link name="pxmark4s/left_back_coxa_link">
    <visual>
      <origin rpy="0 0 0" xyz="0 0 0"/>
      <geometry>
        <mesh filename="package://interbotix_xshexapod_descriptions/meshes/pxmark4s_meshes/pxmark4s_coxa_link.stl" scale="0.001 0.001 0.001"/>
      </geometry>
      <material name="interbotix_black"/>
    </visual>
    <collision>
      <origin rpy="0 0 0" xyz="0 0 0"/>
      <geometry>
        <mesh filename="package://interbotix_xshexapod_descriptions/meshes/pxmark4s_meshes/pxmark4s_coxa_link.stl" scale="0.001 0.001 0.001"/>
      </geometry>
    </collision>
    <inertial>
      <origin rpy="0 0 0" xyz="0.019066 -0.000002 0.006577"/>
      <mass value="0.02471"/>
      <inertia ixx="0.0000215400" ixy="-0.00000000122" ixz="-0.00000192741" iyy="0.00002657000" iyz="-0.00000000001" izz="0.00002925000"/>
    </inertial>
  </link>
  <joint name="left_back_femur" type="revolute">
    <axis xyz="0 1 0"/>
    <limit effort="3" lower="-1.710422666954443" upper="1.5707963267948966" velocity="3.141592653589793"/>
    <origin rpy="0 0 0" xyz="0.052907539 0 0"/>
    <parent link="pxmark4s/left_back_coxa_link"/>
    <child link="pxmark4s/left_back_femur_link"/>
  </joint>
  <transmission name="trans_left_back_femur">
    <type>transmission_interface/SimpleTransmission</type>
    <joint name="left_back_femur">
      <hardwareInterface>hardware_interface/EffortJointInterface</hardwareInterface>
    </joint>
    <actuator name="left_back_femur_motor">
      <mechanicalReduction>1</mechanicalReduction>
    </actuator>
  </transmission>
  <link name="pxmark4s/left_back_femur_link">
    <visual>
      <origin rpy="0 0 0" xyz="0 0 0"/>
      <geometry>
        <mesh filename="package://interbotix_xshexapod_descriptions/meshes/pxmark4s_meshes/pxmark4s_femur_link.stl" scale="0.001 0.001 0.001"/>
      </geometry>
      <material name="interbotix_black"/>
    </visual>
    <collision>
      <origin rpy="0 0 0" xyz="0 0 0"/>
      <geometry>
        <mesh filename="package://interbotix_xshexapod_descriptions/meshes/pxmark4s_meshes/pxmark4s_femur_link.stl" scale="0.001 0.001 0.001"/>
      </geometry>
    </collision>
    <inertial>
      <origin rpy="0 0 0" xyz="0.019579 -0.000301 -0.000582"/>
      <mass value="0.092834"/>
      <inertia ixx="0.0000300200" ixy="0.0000002711" ixz="0.0000048494" iyy="0.0000776600" iyz="0.0000000003" izz="0.0000896200"/>
    </inertial>
  </link>
  <joint name="left_back_tibia" type="revolute">
    <axis xyz="0 1 0"/>
    <limit effort="3" lower="-0.7853981633974483" upper="2.181661564992912" velocity="3.141592653589793"/>
    <origin rpy="0 0 0" xyz="0.06 0 -0.015"/>
    <parent link="pxmark4s/left_back_femur_link"/>
    <child link="pxmark4s/left_back_tibia_link"/>
  </joint>
  <transmission name="trans_left_back_tibia">
    <type>transmission_interface/SimpleTransmission</type>
    <joint name="left_back_tibia">
      <hardwareInterface>hardware_interface/EffortJointInterface</hardwareInterface>
    </joint>
    <actuator name="left_back_tibia_motor">
      <mechanicalReduction>1</mechanicalReduction>
    </actuator>
  </transmission>
  <link name="pxmark4s/left_back_tibia_link">
    <visual>
      <origin rpy="0 0 0" xyz="0 0 0"/>
      <geometry>
        <mesh filename="package://interbotix_xshexapod_descriptions/meshes/pxmark4s_meshes/pxmark4s_tibia_link.stl" scale="0.001 0.001 0.001"/>
      </geometry>
      <material name="interbotix_black"/>
    </visual>
    <collision>
      <origin rpy="0 0 0" xyz="0 0 0"/>
      <geometry>
        <mesh filename="package://interbotix_xshexapod_descriptions/meshes/pxmark4s_meshes/pxmark4s_tibia_link.stl" scale="0.001 0.001 0.001"/>
      </geometry>
    </collision>
    <inertial>
      <origin rpy="0 0 0" xyz="0.035812 0.000035 -0.011522"/>
      <mass value="0.178825"/>
      <inertia ixx="0.0001773000" ixy="-0.0000014230" ixz="0.0001789000" iyy="0.0005185000" iyz="0.0000006181" izz="0.0003797000"/>
    </inertial>
  </link>
  <joint name="left_back_foot" type="fixed">
    <origin rpy="0 0 0" xyz="0.095 0 -0.09"/>
    <parent link="pxmark4s/left_back_tibia_link"/>
    <child link="pxmark4s/left_back_foot_link"/>
  </joint>
  <link name="pxmark4s/left_back_foot_link"/>
</robot>
