<?xml version='1.0' encoding='utf-8'?>
<robot name="estimated_robot">
  <link name="link_0">
    <visual>
      <origin xyz="-0.006815875 -0.0013440158 0.013797351" rpy="0.0 0.0 0.0" />
      <geometry>
        <mesh filename="mesh/solo8_35_seg/4_deg_20_cams/V0000/0000.stl" scale="1 1 1" />
      </geometry>
      <material name="material_0">
        <color rgba="0.0 0.0 0.5 1" />
      </material>
    </visual>
    <collision>
      <origin xyz="-0.006815875 -0.0013440158 0.013797351" rpy="0.0 0.0 0.0" />
      <geometry>
        <mesh filename="mesh/solo8_35_seg/4_deg_20_cams/V0000/0000.stl" scale="1 1 1" />
      </geometry>
    </collision>
    <inertial>
      <origin xyz="-0.006815875 -0.0013440158 0.013797351" rpy="0.0 0.0 0.0" />
      <mass value="1.0" />
      <inertia ixx="0.1" ixy="0.0" ixz="0.0" iyy="0.1" iyz="0.0" izz="0.1" />
    </inertial>
  </link>
  <link name="link_8">
    <visual>
      <origin xyz="0.0036056195317794304 -0.03157753221267007 -0.065194598660561" rpy="0.0 0.0 0.0" />
      <geometry>
        <mesh filename="mesh/solo8_35_seg/4_deg_20_cams/V0000/0008.stl" scale="1 1 1" />
      </geometry>
      <material name="material_8">
        <color rgba="0.9991087344028523 0.07334785766158336 0.0 1" />
      </material>
    </visual>
    <collision>
      <origin xyz="0.0036056195317794304 -0.03157753221267007 -0.065194598660561" rpy="0.0 0.0 0.0" />
      <geometry>
        <mesh filename="mesh/solo8_35_seg/4_deg_20_cams/V0000/0008.stl" scale="1 1 1" />
      </geometry>
    </collision>
    <inertial>
      <origin xyz="0.0036056195317794304 -0.03157753221267007 -0.065194598660561" rpy="0.0 0.0 0.0" />
      <mass value="1.0" />
      <inertia ixx="0.1" ixy="0.0" ixz="0.0" iyy="0.1" iyz="0.0" izz="0.1" />
    </inertial>
  </link>
  <link name="link_1">
    <visual>
      <origin xyz="0.00027865215687625233 0.041400229603722555 -0.08863503634304049" rpy="0.0 0.0 0.0" />
      <geometry>
        <mesh filename="mesh/solo8_35_seg/4_deg_20_cams/V0000/0001.stl" scale="1 1 1" />
      </geometry>
      <material name="material_1">
        <color rgba="0.0 0.0 0.999108734402852 1" />
      </material>
    </visual>
    <collision>
      <origin xyz="0.00027865215687625233 0.041400229603722555 -0.08863503634304049" rpy="0.0 0.0 0.0" />
      <geometry>
        <mesh filename="mesh/solo8_35_seg/4_deg_20_cams/V0000/0001.stl" scale="1 1 1" />
      </geometry>
    </collision>
    <inertial>
      <origin xyz="0.00027865215687625233 0.041400229603722555 -0.08863503634304049" rpy="0.0 0.0 0.0" />
      <mass value="1.0" />
      <inertia ixx="0.1" ixy="0.0" ixz="0.0" iyy="0.1" iyz="0.0" izz="0.1" />
    </inertial>
  </link>
  <link name="link_2">
    <visual>
      <origin xyz="-0.0043754917332295695 0.03765197324336128 -0.07639591912287576" rpy="0.0 0.0 0.0" />
      <geometry>
        <mesh filename="mesh/solo8_35_seg/4_deg_20_cams/V0000/0002.stl" scale="1 1 1" />
      </geometry>
      <material name="material_2">
        <color rgba="0.0 0.3784313725490196 1.0 1" />
      </material>
    </visual>
    <collision>
      <origin xyz="-0.0043754917332295695 0.03765197324336128 -0.07639591912287576" rpy="0.0 0.0 0.0" />
      <geometry>
        <mesh filename="mesh/solo8_35_seg/4_deg_20_cams/V0000/0002.stl" scale="1 1 1" />
      </geometry>
    </collision>
    <inertial>
      <origin xyz="-0.0043754917332295695 0.03765197324336128 -0.07639591912287576" rpy="0.0 0.0 0.0" />
      <mass value="1.0" />
      <inertia ixx="0.1" ixy="0.0" ixz="0.0" iyy="0.1" iyz="0.0" izz="0.1" />
    </inertial>
  </link>
  <link name="link_4">
    <visual>
      <origin xyz="-0.005869022887860703 -0.04086562239122979 -0.07963684963674185" rpy="0.0 0.0 0.0" />
      <geometry>
        <mesh filename="mesh/solo8_35_seg/4_deg_20_cams/V0000/0004.stl" scale="1 1 1" />
      </geometry>
      <material name="material_4">
        <color rgba="0.30044275774826057 1.0 0.6672991777356103 1" />
      </material>
    </visual>
    <collision>
      <origin xyz="-0.005869022887860703 -0.04086562239122979 -0.07963684963674185" rpy="0.0 0.0 0.0" />
      <geometry>
        <mesh filename="mesh/solo8_35_seg/4_deg_20_cams/V0000/0004.stl" scale="1 1 1" />
      </geometry>
    </collision>
    <inertial>
      <origin xyz="-0.005869022887860703 -0.04086562239122979 -0.07963684963674185" rpy="0.0 0.0 0.0" />
      <mass value="1.0" />
      <inertia ixx="0.1" ixy="0.0" ixz="0.0" iyy="0.1" iyz="0.0" izz="0.1" />
    </inertial>
  </link>
  <link name="link_3">
    <visual>
      <origin xyz="0.00032462421030235444 -0.009676998019948091 -0.07566259617688734" rpy="0.0 0.0 0.0" />
      <geometry>
        <mesh filename="mesh/solo8_35_seg/4_deg_20_cams/V0000/0003.stl" scale="1 1 1" />
      </geometry>
      <material name="material_3">
        <color rgba="0.0 0.8333333333333334 1.0 1" />
      </material>
    </visual>
    <collision>
      <origin xyz="0.00032462421030235444 -0.009676998019948091 -0.07566259617688734" rpy="0.0 0.0 0.0" />
      <geometry>
        <mesh filename="mesh/solo8_35_seg/4_deg_20_cams/V0000/0003.stl" scale="1 1 1" />
      </geometry>
    </collision>
    <inertial>
      <origin xyz="0.00032462421030235444 -0.009676998019948091 -0.07566259617688734" rpy="0.0 0.0 0.0" />
      <mass value="1.0" />
      <inertia ixx="0.1" ixy="0.0" ixz="0.0" iyy="0.1" iyz="0.0" izz="0.1" />
    </inertial>
  </link>
  <link name="link_6">
    <visual>
      <origin xyz="-0.0007982392203496058 0.011636321626921659 -0.08386257536557329" rpy="0.0 0.0 0.0" />
      <geometry>
        <mesh filename="mesh/solo8_35_seg/4_deg_20_cams/V0000/0006.stl" scale="1 1 1" />
      </geometry>
      <material name="material_6">
        <color rgba="1.0 0.9012345679012348 0.0 1" />
      </material>
    </visual>
    <collision>
      <origin xyz="-0.0007982392203496058 0.011636321626921659 -0.08386257536557329" rpy="0.0 0.0 0.0" />
      <geometry>
        <mesh filename="mesh/solo8_35_seg/4_deg_20_cams/V0000/0006.stl" scale="1 1 1" />
      </geometry>
    </collision>
    <inertial>
      <origin xyz="-0.0007982392203496058 0.011636321626921659 -0.08386257536557329" rpy="0.0 0.0 0.0" />
      <mass value="1.0" />
      <inertia ixx="0.1" ixy="0.0" ixz="0.0" iyy="0.1" iyz="0.0" izz="0.1" />
    </inertial>
  </link>
  <link name="link_7">
    <visual>
      <origin xyz="-0.004707975406381237 0.015289568769383949 -0.10230644693988361" rpy="0.0 0.0 0.0" />
      <geometry>
        <mesh filename="mesh/solo8_35_seg/4_deg_20_cams/V0000/0007.stl" scale="1 1 1" />
      </geometry>
      <material name="material_7">
        <color rgba="1.0 0.48002904865649987 0.0 1" />
      </material>
    </visual>
    <collision>
      <origin xyz="-0.004707975406381237 0.015289568769383949 -0.10230644693988361" rpy="0.0 0.0 0.0" />
      <geometry>
        <mesh filename="mesh/solo8_35_seg/4_deg_20_cams/V0000/0007.stl" scale="1 1 1" />
      </geometry>
    </collision>
    <inertial>
      <origin xyz="-0.004707975406381237 0.015289568769383949 -0.10230644693988361" rpy="0.0 0.0 0.0" />
      <mass value="1.0" />
      <inertia ixx="0.1" ixy="0.0" ixz="0.0" iyy="0.1" iyz="0.0" izz="0.1" />
    </inertial>
  </link>
  <link name="link_5">
    <visual>
      <origin xyz="0.003976478669139444 -0.010850773746486075 -0.08203313799628503" rpy="0.0 0.0 0.0" />
      <geometry>
        <mesh filename="mesh/solo8_35_seg/4_deg_20_cams/V0000/0005.stl" scale="1 1 1" />
      </geometry>
      <material name="material_5">
        <color rgba="0.6672991777356103 1.0 0.30044275774826057 1" />
      </material>
    </visual>
    <collision>
      <origin xyz="0.003976478669139444 -0.010850773746486075 -0.08203313799628503" rpy="0.0 0.0 0.0" />
      <geometry>
        <mesh filename="mesh/solo8_35_seg/4_deg_20_cams/V0000/0005.stl" scale="1 1 1" />
      </geometry>
    </collision>
    <inertial>
      <origin xyz="0.003976478669139444 -0.010850773746486075 -0.08203313799628503" rpy="0.0 0.0 0.0" />
      <mass value="1.0" />
      <inertia ixx="0.1" ixy="0.0" ixz="0.0" iyy="0.1" iyz="0.0" izz="0.1" />
    </inertial>
  </link>
  <joint name="joint_8" type="revolute">
    <parent link="link_0" />
    <child link="link_8" />
    <origin xyz="0.18624433829197393 -0.09232624896294334 0.0047393844283546566" rpy="0.0 0.0 0.0" />
    <axis xyz="0.01593223595374058 -0.9998613623367876 -0.004839417685773863" />
    <limit effort="100" velocity="100" lower="-3.14159" upper="3.14159" />
  </joint>
  <joint name="joint_1" type="revolute">
    <parent link="link_0" />
    <child link="link_1" />
    <origin xyz="-0.19026200517563693 0.08498490783505155 0.0015433221992874335" rpy="0.0 0.0 0.0" />
    <axis xyz="0.017976071985183 0.9996922798007424 0.017094049923225323" />
    <limit effort="100" velocity="100" lower="-3.14159" upper="3.14159" />
  </joint>
  <joint name="joint_2" type="revolute">
    <parent link="link_0" />
    <child link="link_2" />
    <origin xyz="0.19400690912691396 0.08416451287686272 0.005888012745560237" rpy="0.0 0.0 0.0" />
    <axis xyz="0.0015217200768860022 -0.9982105886108946 -0.05977712901351919" />
    <limit effort="100" velocity="100" lower="-3.14159" upper="3.14159" />
  </joint>
  <joint name="joint_4" type="revolute">
    <parent link="link_0" />
    <child link="link_4" />
    <origin xyz="-0.18467284055360658 -0.08632495261239417 -0.0012625081589734827" rpy="0.0 0.0 0.0" />
    <axis xyz="0.020360415816423758 0.999735107265644 -0.010731671274028775" />
    <limit effort="100" velocity="100" lower="-3.14159" upper="3.14159" />
  </joint>
  <joint name="joint_3" type="revolute">
    <parent link="link_8" />
    <child link="link_3" />
    <origin xyz="0.0031986664058810677 -0.04374799088637127 -0.16039135796315251" rpy="0.0 0.0 0.0" />
    <axis xyz="-0.005911145602174317 -0.9999825212241031 0.00012491579680640186" />
    <limit effort="100" velocity="100" lower="-3.14159" upper="3.14159" />
  </joint>
  <joint name="joint_6" type="revolute">
    <parent link="link_1" />
    <child link="link_6" />
    <origin xyz="0.0009867989566478552 0.05139236230438421 -0.16073068134013047" rpy="0.0 0.0 0.0" />
    <axis xyz="0.008041181192847467 0.9987734019690323 -0.048857250477587585" />
    <limit effort="100" velocity="100" lower="-3.14159" upper="3.14159" />
  </joint>
  <joint name="joint_7" type="revolute">
    <parent link="link_2" />
    <child link="link_7" />
    <origin xyz="0.0006259322405421097 0.050500356563287024 -0.16394356507897678" rpy="0.0 0.0 0.0" />
    <axis xyz="-0.026366416627032718 -0.9974150901076358 0.06684272660377025" />
    <limit effort="100" velocity="100" lower="-3.14159" upper="3.14159" />
  </joint>
  <joint name="joint_5" type="revolute">
    <parent link="link_4" />
    <child link="link_5" />
    <origin xyz="-0.009689337387688624 -0.05155055814505652 -0.16049632147512782" rpy="0.0 0.0 0.0" />
    <axis xyz="-0.0012810810471561844 -0.999815412899504 0.019170262385922336" />
    <limit effort="100" velocity="100" lower="-3.14159" upper="3.14159" />
  </joint>
</robot>