<?xml version='1.0' encoding='utf-8'?>
<robot name="estimated_robot">
  <link name="link_1">
    <visual>
      <origin xyz="-0.007954146 0.0019195719 0.028704565" rpy="0.0 0.0 0.0" />
      <geometry>
        <mesh filename="mesh/pxs_45_seg/4_deg_20_cams/V0000/0001.stl" scale="1 1 1" />
      </geometry>
      <material name="material_1">
        <color rgba="0.0 0.0 0.731729055258467 1" />
      </material>
    </visual>
    <collision>
      <origin xyz="-0.007954146 0.0019195719 0.028704565" rpy="0.0 0.0 0.0" />
      <geometry>
        <mesh filename="mesh/pxs_45_seg/4_deg_20_cams/V0000/0001.stl" scale="1 1 1" />
      </geometry>
    </collision>
    <inertial>
      <origin xyz="-0.007954146 0.0019195719 0.028704565" rpy="0.0 0.0 0.0" />
      <mass value="1.0" />
      <inertia ixx="0.1" ixy="0.0" ixz="0.0" iyy="0.1" iyz="0.0" izz="0.1" />
    </inertial>
  </link>
  <link name="link_7">
    <visual>
      <origin xyz="-0.017026693539722415 -0.01795381903818269 -0.004053904506046533" rpy="0.0 0.0 0.0" />
      <geometry>
        <mesh filename="mesh/pxs_45_seg/4_deg_20_cams/V0000/0007.stl" scale="1 1 1" />
      </geometry>
      <material name="material_7">
        <color rgba="0.06008855154965211 0.9745098039215686 0.9076533839342189 1" />
      </material>
    </visual>
    <collision>
      <origin xyz="-0.017026693539722415 -0.01795381903818269 -0.004053904506046533" rpy="0.0 0.0 0.0" />
      <geometry>
        <mesh filename="mesh/pxs_45_seg/4_deg_20_cams/V0000/0007.stl" scale="1 1 1" />
      </geometry>
    </collision>
    <inertial>
      <origin xyz="-0.017026693539722415 -0.01795381903818269 -0.004053904506046533" rpy="0.0 0.0 0.0" />
      <mass value="1.0" />
      <inertia ixx="0.1" ixy="0.0" ixz="0.0" iyy="0.1" iyz="0.0" izz="0.1" />
    </inertial>
  </link>
  <link name="link_10">
    <visual>
      <origin xyz="0.017702224853752918 0.01743471299391594 -0.003218037075248716" rpy="0.0 0.0 0.0" />
      <geometry>
        <mesh filename="mesh/pxs_45_seg/4_deg_20_cams/V0000/0010.stl" scale="1 1 1" />
      </geometry>
      <material name="material_10">
        <color rgba="0.5660974067046173 1.0 0.4016445287792536 1" />
      </material>
    </visual>
    <collision>
      <origin xyz="0.017702224853752918 0.01743471299391594 -0.003218037075248716" rpy="0.0 0.0 0.0" />
      <geometry>
        <mesh filename="mesh/pxs_45_seg/4_deg_20_cams/V0000/0010.stl" scale="1 1 1" />
      </geometry>
    </collision>
    <inertial>
      <origin xyz="0.017702224853752918 0.01743471299391594 -0.003218037075248716" rpy="0.0 0.0 0.0" />
      <mass value="1.0" />
      <inertia ixx="0.1" ixy="0.0" ixz="0.0" iyy="0.1" iyz="0.0" izz="0.1" />
    </inertial>
  </link>
  <link name="link_14">
    <visual>
      <origin xyz="-0.013516355218612663 0.010697622211500668 -0.0029561243441001677" rpy="0.0 0.0 0.0" />
      <geometry>
        <mesh filename="mesh/pxs_45_seg/4_deg_20_cams/V0000/0014.stl" scale="1 1 1" />
      </geometry>
      <material name="material_14">
        <color rgba="1.0 0.6397966594045028 0.0 1" />
      </material>
    </visual>
    <collision>
      <origin xyz="-0.013516355218612663 0.010697622211500668 -0.0029561243441001677" rpy="0.0 0.0 0.0" />
      <geometry>
        <mesh filename="mesh/pxs_45_seg/4_deg_20_cams/V0000/0014.stl" scale="1 1 1" />
      </geometry>
    </collision>
    <inertial>
      <origin xyz="-0.013516355218612663 0.010697622211500668 -0.0029561243441001677" rpy="0.0 0.0 0.0" />
      <mass value="1.0" />
      <inertia ixx="0.1" ixy="0.0" ixz="0.0" iyy="0.1" iyz="0.0" izz="0.1" />
    </inertial>
  </link>
  <link name="link_16">
    <visual>
      <origin xyz="0.01428312471440013 -0.014144680280140695 -0.0029616718748664015" rpy="0.0 0.0 0.0" />
      <geometry>
        <mesh filename="mesh/pxs_45_seg/4_deg_20_cams/V0000/0016.stl" scale="1 1 1" />
      </geometry>
      <material name="material_16">
        <color rgba="1.0 0.24763979665940472 0.0 1" />
      </material>
    </visual>
    <collision>
      <origin xyz="0.01428312471440013 -0.014144680280140695 -0.0029616718748664015" rpy="0.0 0.0 0.0" />
      <geometry>
        <mesh filename="mesh/pxs_45_seg/4_deg_20_cams/V0000/0016.stl" scale="1 1 1" />
      </geometry>
    </collision>
    <inertial>
      <origin xyz="0.01428312471440013 -0.014144680280140695 -0.0029616718748664015" rpy="0.0 0.0 0.0" />
      <mass value="1.0" />
      <inertia ixx="0.1" ixy="0.0" ixz="0.0" iyy="0.1" iyz="0.0" izz="0.1" />
    </inertial>
  </link>
  <link name="link_17">
    <visual>
      <origin xyz="0.0006578710486904416 0.026307493592293202 -0.005733693527874485" rpy="0.0 0.0 0.0" />
      <geometry>
        <mesh filename="mesh/pxs_45_seg/4_deg_20_cams/V0000/0017.stl" scale="1 1 1" />
      </geometry>
      <material name="material_17">
        <color rgba="0.9634581105169343 0.04429920116194641 0.0 1" />
      </material>
    </visual>
    <collision>
      <origin xyz="0.0006578710486904416 0.026307493592293202 -0.005733693527874485" rpy="0.0 0.0 0.0" />
      <geometry>
        <mesh filename="mesh/pxs_45_seg/4_deg_20_cams/V0000/0017.stl" scale="1 1 1" />
      </geometry>
    </collision>
    <inertial>
      <origin xyz="0.0006578710486904416 0.026307493592293202 -0.005733693527874485" rpy="0.0 0.0 0.0" />
      <mass value="1.0" />
      <inertia ixx="0.1" ixy="0.0" ixz="0.0" iyy="0.1" iyz="0.0" izz="0.1" />
    </inertial>
  </link>
  <link name="link_18">
    <visual>
      <origin xyz="-4.568655770539464e-05 -0.014547347957210036 -0.002988256423893252" rpy="0.0 0.0 0.0" />
      <geometry>
        <mesh filename="mesh/pxs_45_seg/4_deg_20_cams/V0000/0018.stl" scale="1 1 1" />
      </geometry>
      <material name="material_18">
        <color rgba="0.7317290552584672 0.0 0.0 1" />
      </material>
    </visual>
    <collision>
      <origin xyz="-4.568655770539464e-05 -0.014547347957210036 -0.002988256423893252" rpy="0.0 0.0 0.0" />
      <geometry>
        <mesh filename="mesh/pxs_45_seg/4_deg_20_cams/V0000/0018.stl" scale="1 1 1" />
      </geometry>
    </collision>
    <inertial>
      <origin xyz="-4.568655770539464e-05 -0.014547347957210036 -0.002988256423893252" rpy="0.0 0.0 0.0" />
      <mass value="1.0" />
      <inertia ixx="0.1" ixy="0.0" ixz="0.0" iyy="0.1" iyz="0.0" izz="0.1" />
    </inertial>
  </link>
  <link name="link_2">
    <visual>
      <origin xyz="-0.022046856134958576 -0.02134097186647925 0.0047475153510213395" rpy="0.0 0.0 0.0" />
      <geometry>
        <mesh filename="mesh/pxs_45_seg/4_deg_20_cams/V0000/0002.stl" scale="1 1 1" />
      </geometry>
      <material name="material_2">
        <color rgba="0.0 0.0 0.963458110516934 1" />
      </material>
    </visual>
    <collision>
      <origin xyz="-0.022046856134958576 -0.02134097186647925 0.0047475153510213395" rpy="0.0 0.0 0.0" />
      <geometry>
        <mesh filename="mesh/pxs_45_seg/4_deg_20_cams/V0000/0002.stl" scale="1 1 1" />
      </geometry>
    </collision>
    <inertial>
      <origin xyz="-0.022046856134958576 -0.02134097186647925 0.0047475153510213395" rpy="0.0 0.0 0.0" />
      <mass value="1.0" />
      <inertia ixx="0.1" ixy="0.0" ixz="0.0" iyy="0.1" iyz="0.0" izz="0.1" />
    </inertial>
  </link>
  <link name="link_15">
    <visual>
      <origin xyz="0.016607207329079637 0.016584757034715458 0.004501881889683035" rpy="0.0 0.0 0.0" />
      <geometry>
        <mesh filename="mesh/pxs_45_seg/4_deg_20_cams/V0000/0015.stl" scale="1 1 1" />
      </geometry>
      <material name="material_15">
        <color rgba="1.0 0.4364560639070445 0.0 1" />
      </material>
    </visual>
    <collision>
      <origin xyz="0.016607207329079637 0.016584757034715458 0.004501881889683035" rpy="0.0 0.0 0.0" />
      <geometry>
        <mesh filename="mesh/pxs_45_seg/4_deg_20_cams/V0000/0015.stl" scale="1 1 1" />
      </geometry>
    </collision>
    <inertial>
      <origin xyz="0.016607207329079637 0.016584757034715458 0.004501881889683035" rpy="0.0 0.0 0.0" />
      <mass value="1.0" />
      <inertia ixx="0.1" ixy="0.0" ixz="0.0" iyy="0.1" iyz="0.0" izz="0.1" />
    </inertial>
  </link>
  <link name="link_9">
    <visual>
      <origin xyz="-0.020683521605248695 0.02090282050226326 0.00016090462999635946" rpy="0.0 0.0 0.0" />
      <geometry>
        <mesh filename="mesh/pxs_45_seg/4_deg_20_cams/V0000/0009.stl" scale="1 1 1" />
      </geometry>
      <material name="material_9">
        <color rgba="0.4016445287792536 1.0 0.5660974067046174 1" />
      </material>
    </visual>
    <collision>
      <origin xyz="-0.020683521605248695 0.02090282050226326 0.00016090462999635946" rpy="0.0 0.0 0.0" />
      <geometry>
        <mesh filename="mesh/pxs_45_seg/4_deg_20_cams/V0000/0009.stl" scale="1 1 1" />
      </geometry>
    </collision>
    <inertial>
      <origin xyz="-0.020683521605248695 0.02090282050226326 0.00016090462999635946" rpy="0.0 0.0 0.0" />
      <mass value="1.0" />
      <inertia ixx="0.1" ixy="0.0" ixz="0.0" iyy="0.1" iyz="0.0" izz="0.1" />
    </inertial>
  </link>
  <link name="link_3">
    <visual>
      <origin xyz="0.023045321079686126 -0.023213292421631462 0.0013363238733830741" rpy="0.0 0.0 0.0" />
      <geometry>
        <mesh filename="mesh/pxs_45_seg/4_deg_20_cams/V0000/0003.stl" scale="1 1 1" />
      </geometry>
      <material name="material_3">
        <color rgba="0.0 0.12745098039215685 1.0 1" />
      </material>
    </visual>
    <collision>
      <origin xyz="0.023045321079686126 -0.023213292421631462 0.0013363238733830741" rpy="0.0 0.0 0.0" />
      <geometry>
        <mesh filename="mesh/pxs_45_seg/4_deg_20_cams/V0000/0003.stl" scale="1 1 1" />
      </geometry>
    </collision>
    <inertial>
      <origin xyz="0.023045321079686126 -0.023213292421631462 0.0013363238733830741" rpy="0.0 0.0 0.0" />
      <mass value="1.0" />
      <inertia ixx="0.1" ixy="0.0" ixz="0.0" iyy="0.1" iyz="0.0" izz="0.1" />
    </inertial>
  </link>
  <link name="link_4">
    <visual>
      <origin xyz="0.0005345249151006132 0.03038026537012012 0.002834111448326988" rpy="0.0 0.0 0.0" />
      <geometry>
        <mesh filename="mesh/pxs_45_seg/4_deg_20_cams/V0000/0004.stl" scale="1 1 1" />
      </geometry>
      <material name="material_4">
        <color rgba="0.0 0.3313725490196077 1.0 1" />
      </material>
    </visual>
    <collision>
      <origin xyz="0.0005345249151006132 0.03038026537012012 0.002834111448326988" rpy="0.0 0.0 0.0" />
      <geometry>
        <mesh filename="mesh/pxs_45_seg/4_deg_20_cams/V0000/0004.stl" scale="1 1 1" />
      </geometry>
    </collision>
    <inertial>
      <origin xyz="0.0005345249151006132 0.03038026537012012 0.002834111448326988" rpy="0.0 0.0 0.0" />
      <mass value="1.0" />
      <inertia ixx="0.1" ixy="0.0" ixz="0.0" iyy="0.1" iyz="0.0" izz="0.1" />
    </inertial>
  </link>
  <link name="link_0">
    <visual>
      <origin xyz="-7.095529454636293e-05 -0.024366495480265177 0.001232126320838929" rpy="0.0 0.0 0.0" />
      <geometry>
        <mesh filename="mesh/pxs_45_seg/4_deg_20_cams/V0000/0000.stl" scale="1 1 1" />
      </geometry>
      <material name="material_0">
        <color rgba="0.0 0.0 0.5 1" />
      </material>
    </visual>
    <collision>
      <origin xyz="-7.095529454636293e-05 -0.024366495480265177 0.001232126320838929" rpy="0.0 0.0 0.0" />
      <geometry>
        <mesh filename="mesh/pxs_45_seg/4_deg_20_cams/V0000/0000.stl" scale="1 1 1" />
      </geometry>
    </collision>
    <inertial>
      <origin xyz="-7.095529454636293e-05 -0.024366495480265177 0.001232126320838929" rpy="0.0 0.0 0.0" />
      <mass value="1.0" />
      <inertia ixx="0.1" ixy="0.0" ixz="0.0" iyy="0.1" iyz="0.0" izz="0.1" />
    </inertial>
  </link>
  <link name="link_12">
    <visual>
      <origin xyz="-0.019495935338985942 -0.01965062833660461 -0.04015491076301998" rpy="0.0 0.0 0.0" />
      <geometry>
        <mesh filename="mesh/pxs_45_seg/4_deg_20_cams/V0000/0012.stl" scale="1 1 1" />
      </geometry>
      <material name="material_12">
        <color rgba="0.9076533839342187 1.0 0.06008855154965209 1" />
      </material>
    </visual>
    <collision>
      <origin xyz="-0.019495935338985942 -0.01965062833660461 -0.04015491076301998" rpy="0.0 0.0 0.0" />
      <geometry>
        <mesh filename="mesh/pxs_45_seg/4_deg_20_cams/V0000/0012.stl" scale="1 1 1" />
      </geometry>
    </collision>
    <inertial>
      <origin xyz="-0.019495935338985942 -0.01965062833660461 -0.04015491076301998" rpy="0.0 0.0 0.0" />
      <mass value="1.0" />
      <inertia ixx="0.1" ixy="0.0" ixz="0.0" iyy="0.1" iyz="0.0" izz="0.1" />
    </inertial>
  </link>
  <link name="link_5">
    <visual>
      <origin xyz="0.015913014159503247 0.016370839820688904 -0.03817961127592226" rpy="0.0 0.0 0.0" />
      <geometry>
        <mesh filename="mesh/pxs_45_seg/4_deg_20_cams/V0000/0005.stl" scale="1 1 1" />
      </geometry>
      <material name="material_5">
        <color rgba="0.0 0.5509803921568628 1.0 1" />
      </material>
    </visual>
    <collision>
      <origin xyz="0.015913014159503247 0.016370839820688904 -0.03817961127592226" rpy="0.0 0.0 0.0" />
      <geometry>
        <mesh filename="mesh/pxs_45_seg/4_deg_20_cams/V0000/0005.stl" scale="1 1 1" />
      </geometry>
    </collision>
    <inertial>
      <origin xyz="0.015913014159503247 0.016370839820688904 -0.03817961127592226" rpy="0.0 0.0 0.0" />
      <mass value="1.0" />
      <inertia ixx="0.1" ixy="0.0" ixz="0.0" iyy="0.1" iyz="0.0" izz="0.1" />
    </inertial>
  </link>
  <link name="link_6">
    <visual>
      <origin xyz="-0.01720095673571226 0.017850779734272237 -0.037169908558762274" rpy="0.0 0.0 0.0" />
      <geometry>
        <mesh filename="mesh/pxs_45_seg/4_deg_20_cams/V0000/0006.stl" scale="1 1 1" />
      </geometry>
      <material name="material_6">
        <color rgba="0.0 0.7549019607843137 1.0 1" />
      </material>
    </visual>
    <collision>
      <origin xyz="-0.01720095673571226 0.017850779734272237 -0.037169908558762274" rpy="0.0 0.0 0.0" />
      <geometry>
        <mesh filename="mesh/pxs_45_seg/4_deg_20_cams/V0000/0006.stl" scale="1 1 1" />
      </geometry>
    </collision>
    <inertial>
      <origin xyz="-0.01720095673571226 0.017850779734272237 -0.037169908558762274" rpy="0.0 0.0 0.0" />
      <mass value="1.0" />
      <inertia ixx="0.1" ixy="0.0" ixz="0.0" iyy="0.1" iyz="0.0" izz="0.1" />
    </inertial>
  </link>
  <link name="link_11">
    <visual>
      <origin xyz="0.019137232093489692 -0.01933914180367302 -0.04046206301235678" rpy="0.0 0.0 0.0" />
      <geometry>
        <mesh filename="mesh/pxs_45_seg/4_deg_20_cams/V0000/0011.stl" scale="1 1 1" />
      </geometry>
      <material name="material_11">
        <color rgba="0.7432005060088547 1.0 0.2245414294750162 1" />
      </material>
    </visual>
    <collision>
      <origin xyz="0.019137232093489692 -0.01933914180367302 -0.04046206301235678" rpy="0.0 0.0 0.0" />
      <geometry>
        <mesh filename="mesh/pxs_45_seg/4_deg_20_cams/V0000/0011.stl" scale="1 1 1" />
      </geometry>
    </collision>
    <inertial>
      <origin xyz="0.019137232093489692 -0.01933914180367302 -0.04046206301235678" rpy="0.0 0.0 0.0" />
      <mass value="1.0" />
      <inertia ixx="0.1" ixy="0.0" ixz="0.0" iyy="0.1" iyz="0.0" izz="0.1" />
    </inertial>
  </link>
  <link name="link_13">
    <visual>
      <origin xyz="0.00024736878041711546 0.02616366754878524 -0.03518506027443789" rpy="0.0 0.0 0.0" />
      <geometry>
        <mesh filename="mesh/pxs_45_seg/4_deg_20_cams/V0000/0013.stl" scale="1 1 1" />
      </geometry>
      <material name="material_13">
        <color rgba="1.0 0.8286129266521426 0.0 1" />
      </material>
    </visual>
    <collision>
      <origin xyz="0.00024736878041711546 0.02616366754878524 -0.03518506027443789" rpy="0.0 0.0 0.0" />
      <geometry>
        <mesh filename="mesh/pxs_45_seg/4_deg_20_cams/V0000/0013.stl" scale="1 1 1" />
      </geometry>
    </collision>
    <inertial>
      <origin xyz="0.00024736878041711546 0.02616366754878524 -0.03518506027443789" rpy="0.0 0.0 0.0" />
      <mass value="1.0" />
      <inertia ixx="0.1" ixy="0.0" ixz="0.0" iyy="0.1" iyz="0.0" izz="0.1" />
    </inertial>
  </link>
  <link name="link_8">
    <visual>
      <origin xyz="0.00021004106773528895 -0.02466523935489162 -0.03469635909259357" rpy="0.0 0.0 0.0" />
      <geometry>
        <mesh filename="mesh/pxs_45_seg/4_deg_20_cams/V0000/0008.stl" scale="1 1 1" />
      </geometry>
      <material name="material_8">
        <color rgba="0.2245414294750158 1.0 0.7432005060088551 1" />
      </material>
    </visual>
    <collision>
      <origin xyz="0.00021004106773528895 -0.02466523935489162 -0.03469635909259357" rpy="0.0 0.0 0.0" />
      <geometry>
        <mesh filename="mesh/pxs_45_seg/4_deg_20_cams/V0000/0008.stl" scale="1 1 1" />
      </geometry>
    </collision>
    <inertial>
      <origin xyz="0.00021004106773528895 -0.02466523935489162 -0.03469635909259357" rpy="0.0 0.0 0.0" />
      <mass value="1.0" />
      <inertia ixx="0.1" ixy="0.0" ixz="0.0" iyy="0.1" iyz="0.0" izz="0.1" />
    </inertial>
  </link>
  <joint name="joint_7" type="revolute">
    <parent link="link_1" />
    <child link="link_7" />
    <origin xyz="-0.12825038938035205 -0.06755324601957183 0.00645787647799051" rpy="0.0 0.0 0.0" />
    <axis xyz="0.023723705261262183 0.0028154686474129993 0.9997145887426933" />
    <limit effort="100" velocity="100" lower="-3.14159" upper="3.14159" />
  </joint>
  <joint name="joint_10" type="revolute">
    <parent link="link_1" />
    <child link="link_10" />
    <origin xyz="0.12243944108176344 0.06264369512814674 0.0066980610125485646" rpy="0.0 0.0 0.0" />
    <axis xyz="0.002368788516710755 -0.07992789117590807 0.9967978335917146" />
    <limit effort="100" velocity="100" lower="-3.14159" upper="3.14159" />
  </joint>
  <joint name="joint_14" type="revolute">
    <parent link="link_1" />
    <child link="link_14" />
    <origin xyz="-0.12660599881199647 0.06883616337008808 0.005417839479823522" rpy="0.0 0.0 0.0" />
    <axis xyz="-0.01253472543340409 0.01252749072447357 0.9998429589862887" />
    <limit effort="100" velocity="100" lower="-3.14159" upper="3.14159" />
  </joint>
  <joint name="joint_16" type="revolute">
    <parent link="link_1" />
    <child link="link_16" />
    <origin xyz="0.12897948512503926 -0.06925216428572768 0.005681924019948159" rpy="0.0 0.0 0.0" />
    <axis xyz="-0.012652576051735417 0.016660011749493605 0.9997811542171426" />
    <limit effort="100" velocity="100" lower="-3.14159" upper="3.14159" />
  </joint>
  <joint name="joint_17" type="revolute">
    <parent link="link_1" />
    <child link="link_17" />
    <origin xyz="-0.001065832653341505 0.09571819738051182 0.00799960996664776" rpy="0.0 0.0 0.0" />
    <axis xyz="0.041601873203843946 -0.052740843121366274 0.99774129292757" />
    <limit effort="100" velocity="100" lower="-3.14159" upper="3.14159" />
  </joint>
  <joint name="joint_18" type="revolute">
    <parent link="link_1" />
    <child link="link_18" />
    <origin xyz="-0.00025997173594974766 -0.1002679169830518 0.008013867217275181" rpy="0.0 0.0 0.0" />
    <axis xyz="-0.0411986755420698 -0.06353815254019358 0.9971286638670851" />
    <limit effort="100" velocity="100" lower="-3.14159" upper="3.14159" />
  </joint>
  <joint name="joint_2" type="revolute">
    <parent link="link_7" />
    <child link="link_2" />
    <origin xyz="-0.039027491079843185 -0.03950116070357905 -0.008448242778999616" rpy="0.0 0.0 0.0" />
    <axis xyz="-0.724000963531513 0.6895247441490353 -0.01944818787569331" />
    <limit effort="100" velocity="100" lower="-3.14159" upper="3.14159" />
  </joint>
  <joint name="joint_15" type="revolute">
    <parent link="link_10" />
    <child link="link_15" />
    <origin xyz="0.040894752474738894 0.04036550341355763 -0.0061783740488235" rpy="0.0 0.0 0.0" />
    <axis xyz="0.6967577818976588 -0.7171008702432462 0.017173679321386543" />
    <limit effort="100" velocity="100" lower="-3.14159" upper="3.14159" />
  </joint>
  <joint name="joint_9" type="revolute">
    <parent link="link_14" />
    <child link="link_9" />
    <origin xyz="-0.037109875763861405 0.03450714403111012 -0.0036787331347421315" rpy="0.0 0.0 0.0" />
    <axis xyz="0.7140433270945136 0.6996010993775824 -0.026465615078355792" />
    <limit effort="100" velocity="100" lower="-3.14159" upper="3.14159" />
  </joint>
  <joint name="joint_3" type="revolute">
    <parent link="link_16" />
    <child link="link_3" />
    <origin xyz="0.03641429477603328 -0.036370891945480516 -0.004628810374317352" rpy="0.0 0.0 0.0" />
    <axis xyz="-0.725899873600006 -0.6876216899486018 -0.015677532322535104" />
    <limit effort="100" velocity="100" lower="-3.14159" upper="3.14159" />
  </joint>
  <joint name="joint_4" type="revolute">
    <parent link="link_17" />
    <child link="link_4" />
    <origin xyz="0.0011319865844809356 0.05627041179923378 -0.007842867209411084" rpy="0.0 0.0 0.0" />
    <axis xyz="-0.9999426460061462 -0.0014502123725812187 0.010611389272919559" />
    <limit effort="100" velocity="100" lower="-3.14159" upper="3.14159" />
  </joint>
  <joint name="joint_0" type="revolute">
    <parent link="link_18" />
    <child link="link_0" />
    <origin xyz="-0.0002599347444849114 -0.05276653415380948 -0.006076409450086633" rpy="0.0 0.0 0.0" />
    <axis xyz="-0.9997327886425535 0.010489055529469314 0.020599296761863867" />
    <limit effort="100" velocity="100" lower="-3.14159" upper="3.14159" />
  </joint>
  <joint name="joint_12" type="revolute">
    <parent link="link_2" />
    <child link="link_12" />
    <origin xyz="-0.03934500212627201 -0.03927899947851356 -0.009343174595650322" rpy="0.0 0.0 0.0" />
    <axis xyz="-0.7239071823418464 0.6896416131837125 0.018783948446889225" />
    <limit effort="100" velocity="100" lower="-3.14159" upper="3.14159" />
  </joint>
  <joint name="joint_5" type="revolute">
    <parent link="link_15" />
    <child link="link_5" />
    <origin xyz="0.04510388545702146 0.04517263533507834 -0.011892829255498422" rpy="0.0 0.0 0.0" />
    <axis xyz="-0.7091832183456501 0.7048721709807153 0.014641905403307818" />
    <limit effort="100" velocity="100" lower="-3.14159" upper="3.14159" />
  </joint>
  <joint name="joint_6" type="revolute">
    <parent link="link_9" />
    <child link="link_6" />
    <origin xyz="-0.04572412330211548 0.044555045497738796 -0.014516597432362893" rpy="0.0 0.0 0.0" />
    <axis xyz="0.6836696663492496 0.7275570139345572 0.0570664418773094" />
    <limit effort="100" velocity="100" lower="-3.14159" upper="3.14159" />
  </joint>
  <joint name="joint_11" type="revolute">
    <parent link="link_3" />
    <child link="link_11" />
    <origin xyz="0.04204001146964065 -0.04166258643472327 -0.010372637608133263" rpy="0.0 0.0 0.0" />
    <axis xyz="0.7006104701770319 0.7128743257118005 -0.030905740878743773" />
    <limit effort="100" velocity="100" lower="-3.14159" upper="3.14159" />
  </joint>
  <joint name="joint_13" type="revolute">
    <parent link="link_4" />
    <child link="link_13" />
    <origin xyz="-0.00015027688180296818 0.06431116297445683 -0.014461962932189194" rpy="0.0 0.0 0.0" />
    <axis xyz="-0.9986165711698625 -0.02619317954669883 -0.04559452960807328" />
    <limit effort="100" velocity="100" lower="-3.14159" upper="3.14159" />
  </joint>
  <joint name="joint_8" type="revolute">
    <parent link="link_0" />
    <child link="link_8" />
    <origin xyz="0.00010715403214686951 -0.06389364060680361 -0.014435221942722423" rpy="0.0 0.0 0.0" />
    <axis xyz="-0.9999065036050371 0.011520104985693568 0.0073669009405986" />
    <limit effort="100" velocity="100" lower="-3.14159" upper="3.14159" />
  </joint>
</robot>