<?xml version='1.0' encoding='utf-8'?>
<robot name="estimated_robot">
  <link name="link_5">
    <visual>
      <origin xyz="0.0014928468 -0.0026043802 0.0444168" rpy="0.0 0.0 0.0" />
      <geometry>
        <mesh filename="mesh/ur5_20_seg/4_deg_20_cams/V0000/0005.stl" scale="1 1 1" />
      </geometry>
      <material name="material_5">
        <color rgba="1.0 0.27668845315904156 0.0 1" />
      </material>
    </visual>
    <collision>
      <origin xyz="0.0014928468 -0.0026043802 0.0444168" rpy="0.0 0.0 0.0" />
      <geometry>
        <mesh filename="mesh/ur5_20_seg/4_deg_20_cams/V0000/0005.stl" scale="1 1 1" />
      </geometry>
    </collision>
    <inertial>
      <origin xyz="0.0014928468 -0.0026043802 0.0444168" rpy="0.0 0.0 0.0" />
      <mass value="1.0" />
      <inertia ixx="0.1" ixy="0.0" ixz="0.0" iyy="0.1" iyz="0.0" izz="0.1" />
    </inertial>
  </link>
  <link name="link_1">
    <visual>
      <origin xyz="-0.0020327757449668804 0.014837000767435955 0.08994051271876799" rpy="0.0 0.0 0.0" />
      <geometry>
        <mesh filename="mesh/ur5_20_seg/4_deg_20_cams/V0000/0001.stl" scale="1 1 1" />
      </geometry>
      <material name="material_1">
        <color rgba="0.0 0.1588235294117647 1.0 1" />
      </material>
    </visual>
    <collision>
      <origin xyz="-0.0020327757449668804 0.014837000767435955 0.08994051271876799" rpy="0.0 0.0 0.0" />
      <geometry>
        <mesh filename="mesh/ur5_20_seg/4_deg_20_cams/V0000/0001.stl" scale="1 1 1" />
      </geometry>
    </collision>
    <inertial>
      <origin xyz="-0.0020327757449668804 0.014837000767435955 0.08994051271876799" rpy="0.0 0.0 0.0" />
      <mass value="1.0" />
      <inertia ixx="0.1" ixy="0.0" ixz="0.0" iyy="0.1" iyz="0.0" izz="0.1" />
    </inertial>
  </link>
  <link name="link_2">
    <visual>
      <origin xyz="0.000430177460270186 0.1162458201328795 0.24779741921424384" rpy="0.0 0.0 0.0" />
      <geometry>
        <mesh filename="mesh/ur5_20_seg/4_deg_20_cams/V0000/0002.stl" scale="1 1 1" />
      </geometry>
      <material name="material_2">
        <color rgba="0.0 0.8333333333333334 1.0 1" />
      </material>
    </visual>
    <collision>
      <origin xyz="0.000430177460270186 0.1162458201328795 0.24779741921424384" rpy="0.0 0.0 0.0" />
      <geometry>
        <mesh filename="mesh/ur5_20_seg/4_deg_20_cams/V0000/0002.stl" scale="1 1 1" />
      </geometry>
    </collision>
    <inertial>
      <origin xyz="0.000430177460270186 0.1162458201328795 0.24779741921424384" rpy="0.0 0.0 0.0" />
      <mass value="1.0" />
      <inertia ixx="0.1" ixy="0.0" ixz="0.0" iyy="0.1" iyz="0.0" izz="0.1" />
    </inertial>
  </link>
  <link name="link_3">
    <visual>
      <origin xyz="0.007010058094784618 -0.06930366120866674 0.20638976093904382" rpy="0.0 0.0 0.0" />
      <geometry>
        <mesh filename="mesh/ur5_20_seg/4_deg_20_cams/V0000/0003.stl" scale="1 1 1" />
      </geometry>
      <material name="material_3">
        <color rgba="0.4901960784313725 1.0 0.4775458570524984 1" />
      </material>
    </visual>
    <collision>
      <origin xyz="0.007010058094784618 -0.06930366120866674 0.20638976093904382" rpy="0.0 0.0 0.0" />
      <geometry>
        <mesh filename="mesh/ur5_20_seg/4_deg_20_cams/V0000/0003.stl" scale="1 1 1" />
      </geometry>
    </collision>
    <inertial>
      <origin xyz="0.007010058094784618 -0.06930366120866674 0.20638976093904382" rpy="0.0 0.0 0.0" />
      <mass value="1.0" />
      <inertia ixx="0.1" ixy="0.0" ixz="0.0" iyy="0.1" iyz="0.0" izz="0.1" />
    </inertial>
  </link>
  <link name="link_4">
    <visual>
      <origin xyz="-0.019140313115529523 0.014656907641161801 0.016907607981282546" rpy="0.0 0.0 0.0" />
      <geometry>
        <mesh filename="mesh/ur5_20_seg/4_deg_20_cams/V0000/0004.stl" scale="1 1 1" />
      </geometry>
      <material name="material_4">
        <color rgba="1.0 0.9012345679012348 0.0 1" />
      </material>
    </visual>
    <collision>
      <origin xyz="-0.019140313115529523 0.014656907641161801 0.016907607981282546" rpy="0.0 0.0 0.0" />
      <geometry>
        <mesh filename="mesh/ur5_20_seg/4_deg_20_cams/V0000/0004.stl" scale="1 1 1" />
      </geometry>
    </collision>
    <inertial>
      <origin xyz="-0.019140313115529523 0.014656907641161801 0.016907607981282546" rpy="0.0 0.0 0.0" />
      <mass value="1.0" />
      <inertia ixx="0.1" ixy="0.0" ixz="0.0" iyy="0.1" iyz="0.0" izz="0.1" />
    </inertial>
  </link>
  <link name="link_0">
    <visual>
      <origin xyz="0.06465529757673634 0.02343625514155584 0.00442971998199182" rpy="0.0 0.0 0.0" />
      <geometry>
        <mesh filename="mesh/ur5_20_seg/4_deg_20_cams/V0000/0000.stl" scale="1 1 1" />
      </geometry>
      <material name="material_0">
        <color rgba="0.0 0.0 0.5 1" />
      </material>
    </visual>
    <collision>
      <origin xyz="0.06465529757673634 0.02343625514155584 0.00442971998199182" rpy="0.0 0.0 0.0" />
      <geometry>
        <mesh filename="mesh/ur5_20_seg/4_deg_20_cams/V0000/0000.stl" scale="1 1 1" />
      </geometry>
    </collision>
    <inertial>
      <origin xyz="0.06465529757673634 0.02343625514155584 0.00442971998199182" rpy="0.0 0.0 0.0" />
      <mass value="1.0" />
      <inertia ixx="0.1" ixy="0.0" ixz="0.0" iyy="0.1" iyz="0.0" izz="0.1" />
    </inertial>
  </link>
  <joint name="joint_1" type="revolute">
    <parent link="link_5" />
    <child link="link_1" />
    <origin xyz="-0.003760807368733271 -0.00150098769619696 0.07714877074757112" rpy="0.0 0.0 0.0" />
    <axis xyz="0.011087188231813596 -0.008592595190431986 0.9999016159427916" />
    <limit effort="100" velocity="100" lower="-3.14159" upper="3.14159" />
  </joint>
  <joint name="joint_2" type="revolute">
    <parent link="link_1" />
    <child link="link_2" />
    <origin xyz="0.004229262478632951 0.02000025876319234 0.08195823923549644" rpy="0.0 0.0 0.0" />
    <axis xyz="-0.05205794610718861 0.9986440521070656 0.00016564504713479505" />
    <limit effort="100" velocity="100" lower="-3.14159" upper="3.14159" />
  </joint>
  <joint name="joint_3" type="revolute">
    <parent link="link_2" />
    <child link="link_3" />
    <origin xyz="-0.008002119345316479 0.05289608429924196 0.43839345734937296" rpy="0.0 0.0 0.0" />
    <axis xyz="0.041213874311807466 0.9972801264935067 0.06110454864660852" />
    <limit effort="100" velocity="100" lower="-3.14159" upper="3.14159" />
  </joint>
  <joint name="joint_4" type="revolute">
    <parent link="link_3" />
    <child link="link_4" />
    <origin xyz="0.014088059863205805 0.031915752365354 0.3723702435682654" rpy="0.0 0.0 0.0" />
    <axis xyz="0.010442377524764285 -0.9984324436311052 0.054987382702310655" />
    <limit effort="100" velocity="100" lower="-3.14159" upper="3.14159" />
  </joint>
  <joint name="joint_0" type="revolute">
    <parent link="link_4" />
    <child link="link_0" />
    <origin xyz="0.025626314926978713 0.029990903475691624 0.011216057669395707" rpy="0.0 0.0 0.0" />
    <axis xyz="-0.9999033278125578 0.011992130386673626 -0.007037317540226142" />
    <limit effort="100" velocity="100" lower="-3.14159" upper="3.14159" />
  </joint>
</robot>